<?xml version="1.0" ?>
<!-- =================================================================================== -->
<!-- |    This document was autogenerated by xacro from /home/joe/medbot_ws/src/medbot_ros2_stack/external/lbr_fri_ros2_stack/lbr_description/urdf/med14_robotiq_2f/med14_robotiq_2f.xacro | -->
<!-- |    EDITING THIS FILE BY HAND IS NOT RECOMMENDED                                 | -->
<!-- =================================================================================== -->
<!-- top level -->
<robot name="med14_robotiq_2f">
  <!-- <xacro:include filename="$(find lbr_description)/urdf/med14_tc/common_properties.xacro" /> -->
  <material name="blue">
    <color rgba="0 0 0.75 1"/>
  </material>
  <material name="grey">
    <color rgba="0.5 0.5 0.5 1"/>
  </material>
  <!-- <xacro:include filename="$(find lbr_description)/urdf/med14_tc/common_properties.xacro" /> -->
  <!-- KDL requires a link without inertia -->
  <link name="lbr_floating_link"/>
  <!--joint between <robot_name>_floating_link and robot_name_link_0-->
  <joint name="lbr_floating_joint" type="fixed">
    <parent link="lbr_floating_link"/>
    <child link="lbr_link_0"/>
  </joint>
  <link name="lbr_link_0">
    <inertial>
      <origin rpy="0 0 0" xyz="-0.001864 0.0 0.077517"/>
      <mass value="8.146413"/>
      <inertia ixx="0.044604" ixy="0.0" ixz="-0.000788" iyy="0.045465" iyz="0.0" izz="0.061904"/>
    </inertial>
    <visual>
      <origin rpy="0 0 0" xyz="0 0 0"/>
      <geometry>
        <mesh filename="/home/yanxi/curobo/src/curobo/content/assets/robot/virtuoso/lbr_description/meshes/med14/visual/link_0.dae"/>
      </geometry>
    </visual>
    <collision>
      <origin rpy="0 0 0" xyz="0 0 0"/>
      <geometry>
        <mesh filename="/home/yanxi/curobo/src/curobo/content/assets/robot/virtuoso/lbr_description/meshes/med14/collision/link_0.stl"/>
      </geometry>
    </collision>
  </link>
  <joint name="lbr_A1" type="revolute">
    <origin rpy="0 0 0" xyz="0.0 0.0 0.147"/>
    <parent link="lbr_link_0"/>
    <child link="lbr_link_1"/>
    <axis xyz="0.0 0.0 1.0"/>
    <limit effort="200" lower="-2.9670597283903604" upper="2.9670597283903604" velocity="1.4835298641951802"/>
    <dynamics damping="10.0" friction="0.1"/>
  </joint>
  <link name="lbr_link_1">
    <inertial>
      <origin rpy="0 0 0" xyz="0.0 -0.033795  0.132404"/>
      <mass value="5.591419"/>
      <inertia ixx="0.044885" ixy="0.0" ixz="0.0" iyy="0.045283" iyz="0.006703" izz="0.016776"/>
    </inertial>
    <visual>
      <origin rpy="0 0 0" xyz="0.0 0.0 -0.147"/>
      <geometry>
        <mesh filename="/home/yanxi/curobo/src/curobo/content/assets/robot/virtuoso/lbr_description/meshes/med14/visual/link_1.dae"/>
      </geometry>
    </visual>
    <collision>
      <origin rpy="0 0 0" xyz="0.0 0.0 -0.147"/>
      <geometry>
        <mesh filename="/home/yanxi/curobo/src/curobo/content/assets/robot/virtuoso/lbr_description/meshes/med14/collision/link_1.stl"/>
      </geometry>
    </collision>
  </link>
  <joint name="lbr_A2" type="revolute">
    <origin rpy="0 0 0" xyz="0.0 -0.01 0.2125"/>
    <parent link="lbr_link_1"/>
    <child link="lbr_link_2"/>
    <axis xyz="0.0 1.0 0.0"/>
    <limit effort="200" lower="-2.0943951023931953" upper="2.0943951023931953" velocity="1.4835298641951802"/>
    <dynamics damping="10.0" friction="0.1"/>
  </joint>
  <link name="lbr_link_2">
    <inertial>
      <origin rpy="0 0 0" xyz="0.000136 0.047546 0.076324"/>
      <mass value="6.013411"/>
      <inertia ixx="0.05833" ixy="-3.5e-05" ixz="5.9e-05" iyy="0.057062" iyz="0.010605" izz="0.017466"/>
    </inertial>
    <visual>
      <origin rpy="0 0 0" xyz="0.0 0.01 -0.3595"/>
      <geometry>
        <mesh filename="/home/yanxi/curobo/src/curobo/content/assets/robot/virtuoso/lbr_description/meshes/med14/visual/link_2.dae"/>
      </geometry>
    </visual>
    <collision>
      <origin rpy="0 0 0" xyz="0.0 0.01 -0.3595"/>
      <geometry>
        <mesh filename="/home/yanxi/curobo/src/curobo/content/assets/robot/virtuoso/lbr_description/meshes/med14/collision/link_2.stl"/>
      </geometry>
    </collision>
  </link>
  <joint name="lbr_A3" type="revolute">
    <origin rpy="0 0 0" xyz="0.0 0.01 0.228"/>
    <parent link="lbr_link_2"/>
    <child link="lbr_link_3"/>
    <axis xyz="0.0 0.0 1.0"/>
    <limit effort="200" lower="-2.9670597283903604" upper="2.9670597283903604" velocity="1.7453292519943295"/>
    <dynamics damping="10.0" friction="0.1"/>
  </joint>
  <link name="lbr_link_3">
    <inertial>
      <origin rpy="0 0 0" xyz="0.0 0.034913 0.123108"/>
      <mass value="3.65879"/>
      <inertia ixx="0.02296" ixy="0.0" ixz="0.0" iyy="0.021913" iyz="-0.004065" izz="0.00814"/>
    </inertial>
    <visual>
      <origin rpy="0 0 0" xyz="0.0 0.0 -0.5875"/>
      <geometry>
        <mesh filename="/home/yanxi/curobo/src/curobo/content/assets/robot/virtuoso/lbr_description/meshes/med14/visual/link_3.dae"/>
      </geometry>
    </visual>
    <collision>
      <origin rpy="0 0 0" xyz="0.0 0.0 -0.5875"/>
      <geometry>
        <mesh filename="/home/yanxi/curobo/src/curobo/content/assets/robot/virtuoso/lbr_description/meshes/med14/collision/link_3.stl"/>
      </geometry>
    </collision>
  </link>
  <joint name="lbr_A4" type="revolute">
    <origin rpy="0 0 0" xyz="0.0 0.0105 0.192"/>
    <parent link="lbr_link_3"/>
    <child link="lbr_link_4"/>
    <axis xyz="0.0 -1.0 0.0"/>
    <limit effort="200" lower="-2.0943951023931953" upper="2.0943951023931953" velocity="1.3089969389957472"/>
    <dynamics damping="10.0" friction="0.1"/>
  </joint>
  <link name="lbr_link_4">
    <inertial>
      <origin rpy="0 0 0" xyz="0.0 -0.039793  0.086944"/>
      <mass value="4.358267"/>
      <inertia ixx="0.034255" ixy="0.0" ixz="0.0" iyy="0.032512" iyz="-0.006365" izz="0.010444"/>
    </inertial>
    <visual>
      <origin rpy="0 0 0" xyz="0.0 -0.0105 -0.7795"/>
      <geometry>
        <mesh filename="/home/yanxi/curobo/src/curobo/content/assets/robot/virtuoso/lbr_description/meshes/med14/visual/link_4.dae"/>
      </geometry>
    </visual>
    <collision>
      <origin rpy="0 0 0" xyz="0.0 -0.0105 -0.7795"/>
      <geometry>
        <mesh filename="/home/yanxi/curobo/src/curobo/content/assets/robot/virtuoso/lbr_description/meshes/med14/collision/link_4.stl"/>
      </geometry>
    </collision>
  </link>
  <joint name="lbr_A5" type="revolute">
    <origin rpy="0 0 0" xyz="0.0 -0.0105 0.2075"/>
    <parent link="lbr_link_4"/>
    <child link="lbr_link_5"/>
    <axis xyz="0.0 0.0 1.0"/>
    <limit effort="200" lower="-2.9670597283903604" upper="2.9670597283903604" velocity="2.2689280275926285"/>
    <dynamics damping="10.0" friction="0.1"/>
  </joint>
  <link name="lbr_link_5">
    <inertial>
      <origin rpy="0 0 0" xyz="0.0 -0.029824  0.076267"/>
      <mass value="1.653015"/>
      <inertia ixx="0.009172" ixy="0.0" ixz="0.0" iyy="0.007714" iyz="0.003033" izz="0.004159"/>
    </inertial>
    <visual>
      <origin rpy="0 0 0" xyz="0.0 0.0 -0.987"/>
      <geometry>
        <mesh filename="/home/yanxi/curobo/src/curobo/content/assets/robot/virtuoso/lbr_description/meshes/med14/visual/link_5.dae"/>
      </geometry>
    </visual>
    <collision>
      <origin rpy="0 0 0" xyz="0.0 0.0 -0.987"/>
      <geometry>
        <mesh filename="/home/yanxi/curobo/src/curobo/content/assets/robot/virtuoso/lbr_description/meshes/med14/collision/link_5.stl"/>
      </geometry>
    </collision>
  </link>
  <joint name="lbr_A6" type="revolute">
    <origin rpy="0 0 0" xyz="0.0 -0.0707 0.1925"/>
    <parent link="lbr_link_5"/>
    <child link="lbr_link_6"/>
    <axis xyz="0.0 1.0 0.0"/>
    <limit effort="200" lower="-2.0943951023931953" upper="2.0943951023931953" velocity="2.356194490192345"/>
    <dynamics damping="10.0" friction="0.1"/>
  </joint>
  <link name="lbr_link_6">
    <inertial>
      <origin rpy="0 0 0" xyz="-1.000e-06 7.102e-02 4.953e-03"/>
      <mass value="2.598211"/>
      <inertia ixx="0.00764" ixy="0.0" ixz="0.0" iyy="0.007355" iyz="0.000336" izz="0.005004"/>
    </inertial>
    <visual>
      <origin rpy="0 0 0" xyz="0.0 0.0707 -1.1795"/>
      <geometry>
        <mesh filename="/home/yanxi/curobo/src/curobo/content/assets/robot/virtuoso/lbr_description/meshes/med14/visual/link_6.dae"/>
      </geometry>
    </visual>
    <collision>
      <origin rpy="0 0 0" xyz="0.0 0.0707 -1.1795"/>
      <geometry>
        <mesh filename="/home/yanxi/curobo/src/curobo/content/assets/robot/virtuoso/lbr_description/meshes/med14/collision/link_6.stl"/>
      </geometry>
    </collision>
  </link>
  <joint name="lbr_A7" type="revolute">
    <origin rpy="0 0 0" xyz="0.0 0.0707 0.091"/>
    <parent link="lbr_link_6"/>
    <child link="lbr_link_7"/>
    <axis xyz="0.0 0.0 1.0"/>
    <limit effort="200" lower="-3.0543261909900763" upper="3.0543261909900763" velocity="2.356194490192345"/>
    <dynamics damping="10.0" friction="0.1"/>
  </joint>
  <link name="lbr_link_7">
    <inertial>
      <origin rpy="0 0 0" xyz="3.0000e-06 -2.0000e-06 1.3782e-02"/>
      <mass value="0.280474"/>
      <inertia ixx="0.000185" ixy="0.0" ixz="0.0" iyy="0.000185" iyz="0.0" izz="0.000323"/>
    </inertial>
    <visual>
      <origin rpy="0 0 0" xyz="0.0 0.0 -1.2705"/>
      <geometry>
        <mesh filename="/home/yanxi/curobo/src/curobo/content/assets/robot/virtuoso/lbr_description/meshes/med14/visual/link_7.dae"/>
      </geometry>
    </visual>
    <collision>
      <origin rpy="0 0 0" xyz="0.0 0.0 -1.2705"/>
      <geometry>
        <mesh filename="/home/yanxi/curobo/src/curobo/content/assets/robot/virtuoso/lbr_description/meshes/med14/collision/link_7.stl"/>
      </geometry>
    </collision>
  </link>
  <link name="lbr_virtuoso">
    <collision>
      <geometry>
        <mesh filename="/home/yanxi/curobo/src/curobo/content/assets/robot/virtuoso/lbr_description/meshes/virtuoso/meshes/SpatulaTool.dae"/>
      </geometry>
      <origin rpy="0 0 0" xyz="0 0 0"/>
    </collision>
    <visual>
      <geometry>
        <mesh filename="/home/yanxi/curobo/src/curobo/content/assets/robot/virtuoso/lbr_description/meshes/virtuoso/meshes/SpatulaTool.stl"/>
      </geometry>
      <origin rpy="0 0 0" xyz="0 0 0"/>
    </visual>
    <inertial>
      <origin rpy="0 0 0" xyz="0 0 0"/>
      <mass value="0.5"/>
      <inertia ixx="0.00081425" ixy="0.0" ixz="0.0" iyy="0.00083034" iyz="0.0" izz="0.00001825"/>
    </inertial>
  </link>
  <joint name="lbr_virtuoso_joint" type="fixed">
    <parent link="lbr_link_7"/>
    <child link="lbr_virtuoso"/>
    <origin rpy="0 0 0" xyz="0 0 0"/>
  </joint>
  <link name="tool_tip"/>
  <joint name="tool_tip_fixed_joint" type="fixed">
    <parent link="lbr_virtuoso"/>
    <child link="tool_tip"/>
    <origin rpy="0 0 0" xyz="0 0 0.1397"/> 
  </joint>
</robot>
