<?xml version="1.0" ?>
<!-- =================================================================================== -->
<!-- |    This document was autogenerated by xacro from ../robots/bimanual_iiwa_robotiq.robot.xacro | -->
<!-- |    EDITING THIS FILE BY HAND IS NOT RECOMMENDED                                 | -->
<!-- =================================================================================== -->
<robot name="bimanual_iiwa">
  <!-- ==================================================================================== -->
  <!-- END effort_transmission macro -->
  <!-- ======================================================================================= -->
  <!--   MATERIALS                                                                             -->
  <!-- ======================================================================================= -->
  <material name="Grey">
    <color rgba="0.7 0.7 0.7 1.0"/>
  </material>
  <material name="black">
    <color rgba="0.0 0.0 0.0 1.0"/>
  </material>
  <link name="world"/>
  <link name="left_iiwa_table">
    <inertial>
      <origin rpy="0 0 0" xyz="0 0 0"/>
      <mass value="200"/>
      <inertia ixx="0.1" ixy="0" ixz="0" iyy="0.1" iyz="0" izz="0.1"/>
    </inertial>
    <visual>
      <origin rpy="0 0 0" xyz="0 0 0"/>
      <geometry>
        <box size="0.61 0.9125 0.59"/>
      </geometry>
      <material name="table_color">
        <color rgba="0.8235294117647058 0.6666666666666666 0.47058823529411764 1.0"/>
      </material>
    </visual>
    <collision>
      <origin rpy="0 0 0" xyz="0 0 0"/>
      <geometry>
        <box size="0.61 0.9125 0.59"/>
      </geometry>
    </collision>
  </link>
  <gazebo reference="left_iiwa_table">
    <visual>
      <material>
        <ambient>0.8235294117647058 0.6666666666666666 0.47058823529411764 1.0</ambient>
        <diffuse>0.50754 0.50754 0.50754 1.0</diffuse>
        <specular>1 1 1 0</specular>
        <emissive>0.0 0.0 0.0 0.0</emissive>
      </material>
    </visual>
  </gazebo>
  <joint name="world_to_left_table" type="fixed">
    <!-- Change this origin to adjust relative pose of robot tables -->
    <origin rpy="0 0 0" xyz="0 0.45625 0.295"/>
    <parent link="world"/>
    <child link="left_iiwa_table"/>
  </joint>
  <joint name="left_iiwa_table_to_left_iiwa" type="fixed">
    <origin rpy="0 0 0" xyz="0 0 0.295"/>
    <parent link="left_iiwa_table"/>
    <child link="left_iiwa_link_0"/>
  </joint>
  <link name="left_iiwa_link_0">
    <inertial>
      <origin rpy="0 0 0" xyz="-0.1 0 0.07"/>
      <mass value="5"/>
      <inertia ixx="0.05" ixy="0" ixz="0" iyy="0.06" iyz="0" izz="0.03"/>
    </inertial>
    <visual>
      <origin rpy="0 0 0" xyz="0 0 0"/>
      <geometry>
        <mesh filename="/home/yanxi/curobo/src/curobo/content/assets/robot/iiwa_allegro_description/meshes/iiwa/visual/link_0.dae"/>
      </geometry>
      <material name="Grey"/>
    </visual>
    <collision>
      <origin rpy="0 0 0" xyz="0 0 0"/>
      <geometry>
        <mesh filename="/home/yanxi/curobo/src/curobo/content/assets/robot/iiwa_allegro_description/meshes/iiwa/collision/link_0.stl"/>
      </geometry>
      <material name="Grey"/>
    </collision>
  </link>
  <joint name="left_iiwa_joint_1" type="revolute">
    <parent link="left_iiwa_link_0"/>
    <child link="left_iiwa_link_1"/>
    <origin rpy="0 0 0" xyz="0 0 0.1575"/>
    <axis xyz="0 0 1"/>
    <limit effort="300" lower="-2.9670597283903604" upper="2.9670597283903604" velocity="1.4835298641951802"/>
    <dynamics damping="20"/>
  </joint>
  <link name="left_iiwa_link_1">
    <inertial>
      <origin rpy="0 0 0" xyz="0 -0.03 0.12"/>
      <mass value="4"/>
      <inertia ixx="0.1" ixy="0" ixz="0" iyy="0.09" iyz="0" izz="0.02"/>
    </inertial>
    <visual>
      <origin rpy="0 0 0" xyz="0 0 0"/>
      <geometry>
        <mesh filename="/home/yanxi/curobo/src/curobo/content/assets/robot/iiwa_allegro_description/meshes/iiwa/visual/link_1.dae"/>
      </geometry>
      <material name="Grey"/>
    </visual>
    <collision>
      <origin rpy="0 0 0" xyz="0 0 0"/>
      <geometry>
        <mesh filename="/home/yanxi/curobo/src/curobo/content/assets/robot/iiwa_allegro_description/meshes/iiwa/collision/link_1.stl"/>
      </geometry>
      <material name="Grey"/>
    </collision>
  </link>
  <joint name="left_iiwa_joint_2" type="revolute">
    <parent link="left_iiwa_link_1"/>
    <child link="left_iiwa_link_2"/>
    <origin rpy="1.5707963267948966   0 3.141592653589793" xyz="0 0 0.2025"/>
    <axis xyz="0 0 1"/>
    <limit effort="300" lower="-2.0943951023931953" upper="2.0943951023931953" velocity="1.4835298641951802"/>
    <dynamics damping="20"/>
  </joint>
  <link name="left_iiwa_link_2">
    <inertial>
      <origin rpy="0 0 0" xyz="0.0003 0.059 0.042"/>
      <mass value="4"/>
      <inertia ixx="0.05" ixy="0" ixz="0" iyy="0.018" iyz="0" izz="0.044"/>
    </inertial>
    <visual>
      <origin rpy="0 0 0" xyz="0 0 0"/>
      <geometry>
        <mesh filename="/home/yanxi/curobo/src/curobo/content/assets/robot/iiwa_allegro_description/meshes/iiwa/visual/link_2.dae"/>
      </geometry>
      <material name="Grey"/>
    </visual>
    <collision>
      <origin rpy="0 0 0" xyz="0 0 0"/>
      <geometry>
        <mesh filename="/home/yanxi/curobo/src/curobo/content/assets/robot/iiwa_allegro_description/meshes/iiwa/collision/link_2.stl"/>
      </geometry>
      <material name="Grey"/>
    </collision>
  </link>
  <joint name="left_iiwa_joint_3" type="revolute">
    <parent link="left_iiwa_link_2"/>
    <child link="left_iiwa_link_3"/>
    <origin rpy="1.5707963267948966 0 3.141592653589793" xyz="0 0.2045 0"/>
    <axis xyz="0 0 1"/>
    <limit effort="300" lower="-2.9670597283903604" upper="2.9670597283903604" velocity="1.7453292519943295"/>
    <dynamics damping="20"/>
  </joint>
  <link name="left_iiwa_link_3">
    <inertial>
      <origin rpy="0 0 0" xyz="0 0.03 0.13"/>
      <mass value="3"/>
      <inertia ixx="0.08" ixy="0" ixz="0" iyy="0.075" iyz="0" izz="0.01"/>
    </inertial>
    <visual>
      <origin rpy="0 0 0" xyz="0 0 0"/>
      <geometry>
        <mesh filename="/home/yanxi/curobo/src/curobo/content/assets/robot/iiwa_allegro_description/meshes/iiwa/visual/link_3.dae"/>
      </geometry>
      <material name="Grey"/>
    </visual>
    <collision>
      <origin rpy="0 0 0" xyz="0 0 0"/>
      <geometry>
        <mesh filename="/home/yanxi/curobo/src/curobo/content/assets/robot/iiwa_allegro_description/meshes/iiwa/collision/link_3.stl"/>
      </geometry>
      <material name="Grey"/>
    </collision>
  </link>
  <joint name="left_iiwa_joint_4" type="revolute">
    <parent link="left_iiwa_link_3"/>
    <child link="left_iiwa_link_4"/>
    <origin rpy="1.5707963267948966 0 0" xyz="0 0 0.2155"/>
    <axis xyz="0 0 1"/>
    <limit effort="300" lower="-2.0943951023931953" upper="2.0943951023931953" velocity="1.3089969389957472"/>
    <dynamics damping="20"/>
  </joint>
  <link name="left_iiwa_link_4">
    <inertial>
      <origin rpy="0 0 0" xyz="0 0.067 0.034"/>
      <mass value="2.7"/>
      <inertia ixx="0.03" ixy="0" ixz="0" iyy="0.01" iyz="0" izz="0.029"/>
    </inertial>
    <visual>
      <origin rpy="0 0 0" xyz="0 0 0"/>
      <geometry>
        <mesh filename="/home/yanxi/curobo/src/curobo/content/assets/robot/iiwa_allegro_description/meshes/iiwa/visual/link_4.dae"/>
      </geometry>
      <material name="Grey"/>
    </visual>
    <collision>
      <origin rpy="0 0 0" xyz="0 0 0"/>
      <geometry>
        <mesh filename="/home/yanxi/curobo/src/curobo/content/assets/robot/iiwa_allegro_description/meshes/iiwa/collision/link_4.stl"/>
      </geometry>
      <material name="Grey"/>
    </collision>
  </link>
  <joint name="left_iiwa_joint_5" type="revolute">
    <parent link="left_iiwa_link_4"/>
    <child link="left_iiwa_link_5"/>
    <origin rpy="-1.5707963267948966 3.141592653589793 0" xyz="0 0.1845 0"/>
    <axis xyz="0 0 1"/>
    <limit effort="300" lower="-2.9670597283903604" upper="2.9670597283903604" velocity="2.2689280275926285"/>
    <dynamics damping="20"/>
  </joint>
  <link name="left_iiwa_link_5">
    <inertial>
      <origin rpy="0 0 0" xyz="0.0001 0.021 0.076"/>
      <mass value="1.7"/>
      <inertia ixx="0.02" ixy="0" ixz="0" iyy="0.018" iyz="0" izz="0.005"/>
    </inertial>
    <visual>
      <origin rpy="0 0 0" xyz="0 0 0"/>
      <geometry>
        <mesh filename="/home/yanxi/curobo/src/curobo/content/assets/robot/iiwa_allegro_description/meshes/iiwa/visual/link_5.dae"/>
      </geometry>
      <material name="Grey"/>
    </visual>
    <collision>
      <origin rpy="0 0 0" xyz="0 0 0"/>
      <geometry>
        <mesh filename="/home/yanxi/curobo/src/curobo/content/assets/robot/iiwa_allegro_description/meshes/iiwa/collision/link_5.stl"/>
      </geometry>
      <material name="Grey"/>
    </collision>
  </link>
  <joint name="left_iiwa_joint_6" type="revolute">
    <parent link="left_iiwa_link_5"/>
    <child link="left_iiwa_link_6"/>
    <origin rpy="1.5707963267948966 0 0" xyz="0 0 0.2155"/>
    <axis xyz="0 0 1"/>
    <limit effort="300" lower="-2.0943951023931953" upper="2.0943951023931953" velocity="2.356194490192345"/>
    <dynamics damping="20"/>
  </joint>
  <link name="left_iiwa_link_6">
    <inertial>
      <origin rpy="0 0 0" xyz="0 0.0006 0.0004"/>
      <mass value="1.8"/>
      <inertia ixx="0.005" ixy="0" ixz="0" iyy="0.0036" iyz="0" izz="0.0047"/>
    </inertial>
    <visual>
      <origin rpy="0 0 0" xyz="0 0 0"/>
      <geometry>
        <mesh filename="/home/yanxi/curobo/src/curobo/content/assets/robot/iiwa_allegro_description/meshes/iiwa/visual/link_6.dae"/>
      </geometry>
      <material name="Grey"/>
    </visual>
    <collision>
      <origin rpy="0 0 0" xyz="0 0 0"/>
      <geometry>
        <mesh filename="/home/yanxi/curobo/src/curobo/content/assets/robot/iiwa_allegro_description/meshes/iiwa/collision/link_6.stl"/>
      </geometry>
      <material name="Grey"/>
    </collision>
  </link>
  <joint name="left_iiwa_joint_7" type="revolute">
    <parent link="left_iiwa_link_6"/>
    <child link="left_iiwa_link_7"/>
    <origin rpy="-1.5707963267948966 3.141592653589793 0" xyz="0 0.081 0"/>
    <axis xyz="0 0 1"/>
    <limit effort="300" lower="-3.0543261909900763" upper="3.0543261909900763" velocity="2.356194490192345"/>
    <dynamics damping="20"/>
  </joint>
  <link name="left_iiwa_link_7">
    <inertial>
      <origin rpy="0 0 0" xyz="0 0 0.02"/>
      <mass value="0.3"/>
      <inertia ixx="0.001" ixy="0" ixz="0" iyy="0.001" iyz="0" izz="0.001"/>
    </inertial>
    <visual>
      <origin rpy="0 0 0" xyz="0 0 0"/>
      <geometry>
        <mesh filename="/home/yanxi/curobo/src/curobo/content/assets/robot/iiwa_allegro_description/meshes/iiwa/visual/link_7.dae"/>
      </geometry>
      <material name="Grey"/>
    </visual>
    <collision>
      <origin rpy="0 0 0" xyz="0 0 0"/>
      <geometry>
        <mesh filename="/home/yanxi/curobo/src/curobo/content/assets/robot/iiwa_allegro_description/meshes/iiwa/collision/link_7.stl"/>
      </geometry>
      <material name="Grey"/>
    </collision>
  </link>
  <joint name="left_iiwa_joint_ee" type="fixed">
    <parent link="left_iiwa_link_7"/>
    <child link="left_iiwa_link_ee"/>
    <origin rpy="0 0 0" xyz="0 0 0.045"/>
  </joint>
  <link name="left_iiwa_link_ee">
    </link>
  <transmission name="left_iiwa_trans_1">
    <type>transmission_interface/SimpleTransmission</type>
    <joint name="left_iiwa_joint_1">
      <hardwareInterface>hardware_interface/EffortJointInterface</hardwareInterface>
    </joint>
    <actuator name="left_iiwa_motor_1">
      <hardwareInterface>hardware_interface/EffortJointInterface</hardwareInterface>
      <mechanicalReduction>1</mechanicalReduction>
    </actuator>
  </transmission>
  <transmission name="left_iiwa_trans_2">
    <type>transmission_interface/SimpleTransmission</type>
    <joint name="left_iiwa_joint_2">
      <hardwareInterface>hardware_interface/EffortJointInterface</hardwareInterface>
    </joint>
    <actuator name="left_iiwa_motor_2">
      <hardwareInterface>hardware_interface/EffortJointInterface</hardwareInterface>
      <mechanicalReduction>1</mechanicalReduction>
    </actuator>
  </transmission>
  <transmission name="left_iiwa_trans_3">
    <type>transmission_interface/SimpleTransmission</type>
    <joint name="left_iiwa_joint_3">
      <hardwareInterface>hardware_interface/EffortJointInterface</hardwareInterface>
    </joint>
    <actuator name="left_iiwa_motor_3">
      <hardwareInterface>hardware_interface/EffortJointInterface</hardwareInterface>
      <mechanicalReduction>1</mechanicalReduction>
    </actuator>
  </transmission>
  <transmission name="left_iiwa_trans_4">
    <type>transmission_interface/SimpleTransmission</type>
    <joint name="left_iiwa_joint_4">
      <hardwareInterface>hardware_interface/EffortJointInterface</hardwareInterface>
    </joint>
    <actuator name="left_iiwa_motor_4">
      <hardwareInterface>hardware_interface/EffortJointInterface</hardwareInterface>
      <mechanicalReduction>1</mechanicalReduction>
    </actuator>
  </transmission>
  <transmission name="left_iiwa_trans_5">
    <type>transmission_interface/SimpleTransmission</type>
    <joint name="left_iiwa_joint_5">
      <hardwareInterface>hardware_interface/EffortJointInterface</hardwareInterface>
    </joint>
    <actuator name="left_iiwa_motor_5">
      <hardwareInterface>hardware_interface/EffortJointInterface</hardwareInterface>
      <mechanicalReduction>1</mechanicalReduction>
    </actuator>
  </transmission>
  <transmission name="left_iiwa_trans_6">
    <type>transmission_interface/SimpleTransmission</type>
    <joint name="left_iiwa_joint_6">
      <hardwareInterface>hardware_interface/EffortJointInterface</hardwareInterface>
    </joint>
    <actuator name="left_iiwa_motor_6">
      <hardwareInterface>hardware_interface/EffortJointInterface</hardwareInterface>
      <mechanicalReduction>1</mechanicalReduction>
    </actuator>
  </transmission>
  <transmission name="left_iiwa_trans_7">
    <type>transmission_interface/SimpleTransmission</type>
    <joint name="left_iiwa_joint_7">
      <hardwareInterface>hardware_interface/EffortJointInterface</hardwareInterface>
    </joint>
    <actuator name="left_iiwa_motor_7">
      <hardwareInterface>hardware_interface/EffortJointInterface</hardwareInterface>
      <mechanicalReduction>1</mechanicalReduction>
    </actuator>
  </transmission>
  <!-- TODO these selfCollide tags are necessary for the arms to be able to collide with
           each other, which definitely seems necessary for bimanual as you want to render
           when one arm collides with other. However, there has been some problem with controlling
           any hands attached to robots when these tags are enabled. I haven't yet tried also
           adding the tags to the hands, which should be done anyways, so give that a shot
           and see if hand can be controlled then with all selfCollide tags active on whole model. -->
  <gazebo reference="left_iiwa_link_0">
    <material>Gazebo/Grey</material>
    <mu1>0.2</mu1>
    <mu2>0.2</mu2>
    <!-- <selfCollide>true</selfCollide> -->
  </gazebo>
  <gazebo reference="left_iiwa_link_1">
    <material>Gazebo/Grey</material>
    <mu1>0.2</mu1>
    <mu2>0.2</mu2>
    <!-- <selfCollide>true</selfCollide> -->
  </gazebo>
  <gazebo reference="left_iiwa_link_2">
    <material>Gazebo/Grey</material>
    <mu1>0.2</mu1>
    <mu2>0.2</mu2>
    <!-- <selfCollide>true</selfCollide> -->
  </gazebo>
  <gazebo reference="left_iiwa_link_3">
    <material>Gazebo/Grey</material>
    <mu1>0.2</mu1>
    <mu2>0.2</mu2>
    <!-- <selfCollide>true</selfCollide> -->
  </gazebo>
  <gazebo reference="left_iiwa_link_4">
    <material>Gazebo/Grey</material>
    <mu1>0.2</mu1>
    <mu2>0.2</mu2>
    <!-- <selfCollide>true</selfCollide> -->
  </gazebo>
  <gazebo reference="left_iiwa_link_5">
    <material>Gazebo/Grey</material>
    <mu1>0.2</mu1>
    <mu2>0.2</mu2>
    <!-- <selfCollide>true</selfCollide> -->
  </gazebo>
  <gazebo reference="left_iiwa_link_6">
    <material>Gazebo/Grey</material>
    <mu1>0.2</mu1>
    <mu2>0.2</mu2>
    <!-- <selfCollide>true</selfCollide> -->
  </gazebo>
  <gazebo reference="left_iiwa_link_7">
    <material>Gazebo/Grey</material>
    <mu1>0.2</mu1>
    <mu2>0.2</mu2>
    <!-- <selfCollide>true</selfCollide> -->
  </gazebo>
  <!-- This file defines macros for constructing the ReFlex1 Takktile hand model. The primary
       macro is 'reflex1' and all other macros are helper macros used by that one. -->
  <!-- END reflex1 macro -->
  <!-- ======================================================================================= -->
  <!--   LINK MACROS                                                                           -->
  <!-- ======================================================================================= -->
  <!-- ======================================================================================= -->
  <!--   TACTILE MACROS                                                                        -->
  <!-- ======================================================================================= -->
  <!-- ======================================================================================= -->
  <!--   JOINT MACROS                                                                          -->
  <!-- ======================================================================================= -->
  <!-- ======================================================================================= -->
  <!--   GAZEBO MACROS                                                                         -->
  <!-- ======================================================================================= -->
  <!-- KINEMATIC CHAIN specifies the actual links and joints in the robot using the
         helper macros defined below in this file -->
  <link name="left_reflex_shell_link">
    <visual>
      <origin rpy="0 0 0" xyz="0 0 0"/>
      <geometry>
        <mesh filename="/home/yanxi/curobo/src/curobo/content/assets/robot/iiwa_allegro_description/meshes/reflex/base_link.stl"/>
      </geometry>
      <material name="black"/>
    </visual>
    <inertial>
      <origin rpy="0 0 0" xyz="0 0 0"/>
      <mass value="0.74"/>
      <inertia ixx="0.0016512483333333333" ixy="0.0" ixz="0.0" iyy="0.0014092066666666668" iyz="0.0" izz="0.0007792816666666667"/>
    </inertial>
    <collision>
      <origin rpy="0 0 0" xyz="0 0 0"/>
      <geometry>
        <mesh filename="/home/yanxi/curobo/src/curobo/content/assets/robot/iiwa_allegro_description/meshes/reflex/base_link_coll.stl"/>
      </geometry>
    </collision>
  </link>
  <joint name="left_reflex_shell_to_pad_joint" type="fixed">
    <origin rpy="1.570796326795 0 -1.570796326795" xyz="0.02 0 0.063"/>
    <parent link="left_reflex_shell_link"/>
    <child link="left_reflex_pad_link"/>
    <axis xyz="0 0 0"/>
  </joint>
  <link name="left_reflex_pad_link">
    <visual>
      <origin rpy="0 0 0" xyz="0 0 0"/>
      <geometry>
        <mesh filename="/home/yanxi/curobo/src/curobo/content/assets/robot/iiwa_allegro_description/meshes/reflex/pad.stl"/>
      </geometry>
      <material name="dark_grey">
        <color rgba="0.2 0.2 0.2 1"/>
      </material>
    </visual>
    <inertial>
      <origin rpy="0 0 0" xyz="0 0 0"/>
      <mass value="0.1"/>
      <inertia ixx="0.0002231416666666667" ixy="0.0" ixz="0.0" iyy="0.00019043333333333337" iyz="0.0" izz="0.00010530833333333334"/>
    </inertial>
    <collision>
      <origin rpy="0 0 0" xyz="0 0 0"/>
      <geometry>
        <mesh filename="/home/yanxi/curobo/src/curobo/content/assets/robot/iiwa_allegro_description/meshes/reflex/pad_coll.stl"/>
      </geometry>
    </collision>
  </link>
  <joint name="left_reflex_palm_joint" type="fixed">
    <origin rpy="3.14159265359 0 1.570796326795" xyz="0 0 0"/>
    <parent link="left_reflex_pad_link"/>
    <child link="left_reflex_palm_link"/>
    <axis xyz="0 0 0"/>
  </joint>
  <link name="left_reflex_palm_link"/>
  <!-- A dummy link to define the end-effector frame -->
  <joint name="left_reflex_preshape_joint_1" type="revolute">
    <parent link="left_reflex_shell_link"/>
    <child link="left_reflex_swivel_link_1"/>
    <limit effort="15" lower="0.0" upper="1.570796326795" velocity="7"/>
    <dynamics damping="5"/>
    <origin rpy="0 0 0" xyz="0.0503973683071414 -0.026 0.063"/>
    <axis xyz="0 0 -1"/>
  </joint>
  <link name="left_reflex_swivel_link_1">
    <visual>
      <origin rpy="0 0 0" xyz="0 0 0"/>
      <geometry>
        <mesh filename="/home/yanxi/curobo/src/curobo/content/assets/robot/iiwa_allegro_description/meshes/reflex/swivel_1.stl"/>
      </geometry>
      <material name="black"/>
    </visual>
    <inertial>
      <origin rpy="0 0 0" xyz="0 0 0"/>
      <mass value="0.01"/>
      <inertia ixx="1.6033333333333332e-06" ixy="0.0" ixz="0.0" iyy="1.153333333333333e-06" iyz="0.0" izz="1.2566666666666664e-06"/>
    </inertial>
    <collision>
      <origin rpy="0 0 0" xyz="0 0 0"/>
      <geometry>
        <mesh filename="/home/yanxi/curobo/src/curobo/content/assets/robot/iiwa_allegro_description/meshes/reflex/swivel_1_coll.stl"/>
      </geometry>
    </collision>
  </link>
  <joint name="left_reflex_proximal_joint_1" type="revolute">
    <child link="left_reflex_proximal_link_1"/>
    <axis xyz="0 -1 0"/>
    <limit effort="15" lower="0.0" upper="3.14159265359" velocity="7"/>
    <dynamics damping="5"/>
    <origin rpy="0 0.28 0" xyz="0.01 0 0.0186"/>
    <parent link="left_reflex_swivel_link_1"/>
  </joint>
  <link name="left_reflex_proximal_link_1">
    <visual>
      <origin rpy="3.14159265359 0 0" xyz="-0.011 0.007 0.011"/>
      <geometry>
        <mesh filename="/home/yanxi/curobo/src/curobo/content/assets/robot/iiwa_allegro_description/meshes/reflex/proximal.stl"/>
      </geometry>
      <material name="black"/>
    </visual>
    <inertial>
      <origin rpy="3.14159265359 0 0" xyz="-0.011 0.007 0.011"/>
      <mass value="0.01"/>
      <inertia ixx="2.295083333333333e-05" ixy="0.0" ixz="0.0" iyy="4.534166666666666e-06" iyz="0.0" izz="1.908333333333333e-05"/>
    </inertial>
    <collision>
      <origin rpy="3.14159265359 0 0" xyz="-0.011 0.007 0.011"/>
      <geometry>
        <mesh filename="/home/yanxi/curobo/src/curobo/content/assets/robot/iiwa_allegro_description/meshes/reflex/proximal_coll.stl"/>
      </geometry>
    </collision>
  </link>
  <joint name="left_reflex_proximal_1_to_pad" type="fixed">
    <origin rpy="1.570796326795 0 -1.570796326795" xyz="0 0 0"/>
    <parent link="left_reflex_proximal_link_1"/>
    <child link="left_reflex_proximal_pad_link_1"/>
  </joint>
  <link name="left_reflex_proximal_pad_link_1">
    <visual>
      <origin rpy="1.570796326795 1.570796326795 0" xyz="-0.008 0.014 -0.002"/>
      <geometry>
        <mesh filename="/home/yanxi/curobo/src/curobo/content/assets/robot/iiwa_allegro_description/meshes/reflex/proximal_pad.stl"/>
      </geometry>
      <material name="dark_grey">
        <color rgba="0.2 0.2 0.2 1"/>
      </material>
    </visual>
    <inertial>
      <origin rpy="1.570796326795 1.570796326795 0" xyz="-0.008 0.014 -0.002"/>
      <mass value="0.01"/>
      <inertia ixx="2.295083333333333e-05" ixy="0.0" ixz="0.0" iyy="4.2216666666666655e-06" iyz="0.0" izz="1.8770833333333333e-05"/>
    </inertial>
    <collision>
      <origin rpy="1.570796326795 1.570796326795 0" xyz="-0.008 0.014 -0.002"/>
      <geometry>
        <mesh filename="/home/yanxi/curobo/src/curobo/content/assets/robot/iiwa_allegro_description/meshes/reflex/proximal_pad_coll.stl"/>
      </geometry>
    </collision>
  </link>
  <joint name="left_reflex_proximal_1_to_flex" type="fixed">
    <origin rpy="0 0 0" xyz="0.07 0 0.004"/>
    <parent link="left_reflex_proximal_link_1"/>
    <child link="left_reflex_flex_link_1"/>
  </joint>
  <link name="left_reflex_flex_link_1">
    <visual>
      <origin rpy="0 0 0" xyz="0.0005 0 -0.003"/>
      <geometry>
        <box size="0.017 0.014 0.0065"/>
      </geometry>
      <material name="gold">
        <color rgba="0.996078431372549 0.8470588235294118 0.36470588235294116 1"/>
      </material>
    </visual>
    <inertial>
      <origin rpy="0 0 0" xyz="0 0 0"/>
      <mass value="0.01"/>
      <inertia ixx="3.5083333333333334e-07" ixy="0.0" ixz="0.0" iyy="2.0833333333333333e-07" iyz="0.0" izz="1.841666666666667e-07"/>
    </inertial>
    <collision>
      <origin rpy="0 0 0" xyz="0 0 0"/>
      <geometry>
        <box size="0.01 0.01 0.01"/>
      </geometry>
    </collision>
  </link>
  <joint name="left_reflex_flex_to_distal_1" type="fixed">
    <origin rpy="0 0 0" xyz="0 0 0"/>
    <parent link="left_reflex_flex_link_1"/>
    <child link="left_reflex_distal_link_1"/>
  </joint>
  <link name="left_reflex_distal_link_1">
    <visual>
      <origin rpy="3.14159265359 0 0" xyz="-0.077 0.007 0.007"/>
      <geometry>
        <mesh filename="/home/yanxi/curobo/src/curobo/content/assets/robot/iiwa_allegro_description/meshes/reflex/distal.stl"/>
      </geometry>
      <material name="black"/>
    </visual>
    <inertial>
      <origin rpy="3.1459 0 0" xyz="-0.077 0.007 0.007"/>
      <mass value="0.01"/>
      <inertia ixx="2.00175e-05" ixy="0.0" ixz="0.0" iyy="1.5083333333333332e-06" iyz="0.0" izz="1.899083333333333e-05"/>
    </inertial>
    <collision>
      <origin rpy="3.14159265359 0 0" xyz="-0.077 0.007 0.007"/>
      <geometry>
        <mesh filename="/home/yanxi/curobo/src/curobo/content/assets/robot/iiwa_allegro_description/meshes/reflex/distal_coll.stl"/>
      </geometry>
    </collision>
  </link>
  <joint name="left_reflex_distal_1_to_pad" type="fixed">
    <origin rpy="1.570796326795 0 -1.570796326795" xyz="-0.01 0 0.001"/>
    <parent link="left_reflex_distal_link_1"/>
    <child link="left_reflex_distal_pad_link_1"/>
  </joint>
  <link name="left_reflex_distal_pad_link_1">
    <visual>
      <origin rpy="1.570796326795 1.570796326795 0" xyz="-0.00825 0.009 0.057"/>
      <geometry>
        <mesh filename="/home/yanxi/curobo/src/curobo/content/assets/robot/iiwa_allegro_description/meshes/reflex/distal_pad.stl"/>
      </geometry>
      <material name="dark_grey">
        <color rgba="0.2 0.2 0.2 1"/>
      </material>
    </visual>
    <inertial>
      <origin rpy="1.570796326795 1.570796326795 0" xyz="-0.00825 0.009 0.057"/>
      <mass value="0.01"/>
      <inertia ixx="2.00175e-05" ixy="0.0" ixz="0.0" iyy="1.2883333333333332e-06" iyz="0.0" izz="1.8770833333333333e-05"/>
    </inertial>
    <collision>
      <origin rpy="1.570796326795 1.570796326795 0" xyz="-0.00825 0.009 0.057"/>
      <geometry>
        <mesh filename="/home/yanxi/curobo/src/curobo/content/assets/robot/iiwa_allegro_description/meshes/reflex/distal_pad_coll.stl"/>
      </geometry>
    </collision>
  </link>
  <joint name="left_reflex_preshape_joint_2" type="revolute">
    <parent link="left_reflex_shell_link"/>
    <child link="left_reflex_swivel_link_2"/>
    <limit effort="15" lower="0.0" upper="1.570796326795" velocity="7"/>
    <dynamics damping="5"/>
    <origin rpy="0 0 0" xyz="0.0503973683071413 0.026 0.063"/>
    <axis xyz="0 0 1"/>
  </joint>
  <link name="left_reflex_swivel_link_2">
    <visual>
      <origin rpy="0 0 0" xyz="0 0 0"/>
      <geometry>
        <mesh filename="/home/yanxi/curobo/src/curobo/content/assets/robot/iiwa_allegro_description/meshes/reflex/swivel_2.stl"/>
      </geometry>
      <material name="black"/>
    </visual>
    <inertial>
      <origin rpy="0 0 0" xyz="0 0 0"/>
      <mass value="0.01"/>
      <inertia ixx="1.6033333333333332e-06" ixy="0.0" ixz="0.0" iyy="1.153333333333333e-06" iyz="0.0" izz="1.2566666666666664e-06"/>
    </inertial>
    <collision>
      <origin rpy="0 0 0" xyz="0 0 0"/>
      <geometry>
        <mesh filename="/home/yanxi/curobo/src/curobo/content/assets/robot/iiwa_allegro_description/meshes/reflex/swivel_2_coll.stl"/>
      </geometry>
    </collision>
  </link>
  <joint name="left_reflex_proximal_joint_2" type="revolute">
    <child link="left_reflex_proximal_link_2"/>
    <axis xyz="0 -1 0"/>
    <limit effort="15" lower="0.0" upper="3.14159265359" velocity="7"/>
    <dynamics damping="5"/>
    <origin rpy="0 0.28 0" xyz="0.01 0 0.0186"/>
    <parent link="left_reflex_swivel_link_2"/>
  </joint>
  <link name="left_reflex_proximal_link_2">
    <visual>
      <origin rpy="3.14159265359 0 0" xyz="-0.011 0.007 0.011"/>
      <geometry>
        <mesh filename="/home/yanxi/curobo/src/curobo/content/assets/robot/iiwa_allegro_description/meshes/reflex/proximal.stl"/>
      </geometry>
      <material name="black"/>
    </visual>
    <inertial>
      <origin rpy="3.14159265359 0 0" xyz="-0.011 0.007 0.011"/>
      <mass value="0.01"/>
      <inertia ixx="2.295083333333333e-05" ixy="0.0" ixz="0.0" iyy="4.534166666666666e-06" iyz="0.0" izz="1.908333333333333e-05"/>
    </inertial>
    <collision>
      <origin rpy="3.14159265359 0 0" xyz="-0.011 0.007 0.011"/>
      <geometry>
        <mesh filename="/home/yanxi/curobo/src/curobo/content/assets/robot/iiwa_allegro_description/meshes/reflex/proximal_coll.stl"/>
      </geometry>
    </collision>
  </link>
  <joint name="left_reflex_proximal_2_to_pad" type="fixed">
    <origin rpy="1.570796326795 0 -1.570796326795" xyz="0 0 0"/>
    <parent link="left_reflex_proximal_link_2"/>
    <child link="left_reflex_proximal_pad_link_2"/>
  </joint>
  <link name="left_reflex_proximal_pad_link_2">
    <visual>
      <origin rpy="1.570796326795 1.570796326795 0" xyz="-0.008 0.014 -0.002"/>
      <geometry>
        <mesh filename="/home/yanxi/curobo/src/curobo/content/assets/robot/iiwa_allegro_description/meshes/reflex/proximal_pad.stl"/>
      </geometry>
      <material name="dark_grey">
        <color rgba="0.2 0.2 0.2 1"/>
      </material>
    </visual>
    <inertial>
      <origin rpy="1.570796326795 1.570796326795 0" xyz="-0.008 0.014 -0.002"/>
      <mass value="0.01"/>
      <inertia ixx="2.295083333333333e-05" ixy="0.0" ixz="0.0" iyy="4.2216666666666655e-06" iyz="0.0" izz="1.8770833333333333e-05"/>
    </inertial>
    <collision>
      <origin rpy="1.570796326795 1.570796326795 0" xyz="-0.008 0.014 -0.002"/>
      <geometry>
        <mesh filename="/home/yanxi/curobo/src/curobo/content/assets/robot/iiwa_allegro_description/meshes/reflex/proximal_pad_coll.stl"/>
      </geometry>
    </collision>
  </link>
  <joint name="left_reflex_proximal_2_to_flex" type="fixed">
    <origin rpy="0 0 0" xyz="0.07 0 0.004"/>
    <parent link="left_reflex_proximal_link_2"/>
    <child link="left_reflex_flex_link_2"/>
  </joint>
  <link name="left_reflex_flex_link_2">
    <visual>
      <origin rpy="0 0 0" xyz="0.0005 0 -0.003"/>
      <geometry>
        <box size="0.017 0.014 0.0065"/>
      </geometry>
      <material name="gold">
        <color rgba="0.996078431372549 0.8470588235294118 0.36470588235294116 1"/>
      </material>
    </visual>
    <inertial>
      <origin rpy="0 0 0" xyz="0 0 0"/>
      <mass value="0.01"/>
      <inertia ixx="3.5083333333333334e-07" ixy="0.0" ixz="0.0" iyy="2.0833333333333333e-07" iyz="0.0" izz="1.841666666666667e-07"/>
    </inertial>
    <collision>
      <origin rpy="0 0 0" xyz="0 0 0"/>
      <geometry>
        <box size="0.01 0.01 0.01"/>
      </geometry>
    </collision>
  </link>
  <joint name="left_reflex_flex_to_distal_2" type="fixed">
    <origin rpy="0 0 0" xyz="0 0 0"/>
    <parent link="left_reflex_flex_link_2"/>
    <child link="left_reflex_distal_link_2"/>
  </joint>
  <link name="left_reflex_distal_link_2">
    <visual>
      <origin rpy="3.14159265359 0 0" xyz="-0.077 0.007 0.007"/>
      <geometry>
        <mesh filename="/home/yanxi/curobo/src/curobo/content/assets/robot/iiwa_allegro_description/meshes/reflex/distal.stl"/>
      </geometry>
      <material name="black"/>
    </visual>
    <inertial>
      <origin rpy="3.1459 0 0" xyz="-0.077 0.007 0.007"/>
      <mass value="0.01"/>
      <inertia ixx="2.00175e-05" ixy="0.0" ixz="0.0" iyy="1.5083333333333332e-06" iyz="0.0" izz="1.899083333333333e-05"/>
    </inertial>
    <collision>
      <origin rpy="3.14159265359 0 0" xyz="-0.077 0.007 0.007"/>
      <geometry>
        <mesh filename="/home/yanxi/curobo/src/curobo/content/assets/robot/iiwa_allegro_description/meshes/reflex/distal_coll.stl"/>
      </geometry>
    </collision>
  </link>
  <joint name="left_reflex_distal_2_to_pad" type="fixed">
    <origin rpy="1.570796326795 0 -1.570796326795" xyz="-0.01 0 0.001"/>
    <parent link="left_reflex_distal_link_2"/>
    <child link="left_reflex_distal_pad_link_2"/>
  </joint>
  <link name="left_reflex_distal_pad_link_2">
    <visual>
      <origin rpy="1.570796326795 1.570796326795 0" xyz="-0.00825 0.009 0.057"/>
      <geometry>
        <mesh filename="/home/yanxi/curobo/src/curobo/content/assets/robot/iiwa_allegro_description/meshes/reflex/distal_pad.stl"/>
      </geometry>
      <material name="dark_grey">
        <color rgba="0.2 0.2 0.2 1"/>
      </material>
    </visual>
    <inertial>
      <origin rpy="1.570796326795 1.570796326795 0" xyz="-0.00825 0.009 0.057"/>
      <mass value="0.01"/>
      <inertia ixx="2.00175e-05" ixy="0.0" ixz="0.0" iyy="1.2883333333333332e-06" iyz="0.0" izz="1.8770833333333333e-05"/>
    </inertial>
    <collision>
      <origin rpy="1.570796326795 1.570796326795 0" xyz="-0.00825 0.009 0.057"/>
      <geometry>
        <mesh filename="/home/yanxi/curobo/src/curobo/content/assets/robot/iiwa_allegro_description/meshes/reflex/distal_pad_coll.stl"/>
      </geometry>
    </collision>
  </link>
  <joint name="left_reflex_proximal_joint_3" type="revolute">
    <child link="left_reflex_proximal_link_3"/>
    <axis xyz="0 -1 0"/>
    <limit effort="15" lower="0.0" upper="3.14159265359" velocity="7"/>
    <dynamics damping="5"/>
    <origin rpy="0 0.28 3.14159265359" xyz="-0.03 0 0.0816"/>
    <parent link="left_reflex_shell_link"/>
  </joint>
  <link name="left_reflex_proximal_link_3">
    <visual>
      <origin rpy="3.14159265359 0 0" xyz="-0.011 0.007 0.011"/>
      <geometry>
        <mesh filename="/home/yanxi/curobo/src/curobo/content/assets/robot/iiwa_allegro_description/meshes/reflex/proximal.stl"/>
      </geometry>
      <material name="black"/>
    </visual>
    <inertial>
      <origin rpy="3.14159265359 0 0" xyz="-0.011 0.007 0.011"/>
      <mass value="0.01"/>
      <inertia ixx="2.295083333333333e-05" ixy="0.0" ixz="0.0" iyy="4.534166666666666e-06" iyz="0.0" izz="1.908333333333333e-05"/>
    </inertial>
    <collision>
      <origin rpy="3.14159265359 0 0" xyz="-0.011 0.007 0.011"/>
      <geometry>
        <mesh filename="/home/yanxi/curobo/src/curobo/content/assets/robot/iiwa_allegro_description/meshes/reflex/proximal_coll.stl"/>
      </geometry>
    </collision>
  </link>
  <joint name="left_reflex_proximal_3_to_pad" type="fixed">
    <origin rpy="1.570796326795 0 -1.570796326795" xyz="0 0 0"/>
    <parent link="left_reflex_proximal_link_3"/>
    <child link="left_reflex_proximal_pad_link_3"/>
  </joint>
  <link name="left_reflex_proximal_pad_link_3">
    <visual>
      <origin rpy="1.570796326795 1.570796326795 0" xyz="-0.008 0.014 -0.002"/>
      <geometry>
        <mesh filename="/home/yanxi/curobo/src/curobo/content/assets/robot/iiwa_allegro_description/meshes/reflex/proximal_pad.stl"/>
      </geometry>
      <material name="dark_grey">
        <color rgba="0.2 0.2 0.2 1"/>
      </material>
    </visual>
    <inertial>
      <origin rpy="1.570796326795 1.570796326795 0" xyz="-0.008 0.014 -0.002"/>
      <mass value="0.01"/>
      <inertia ixx="2.295083333333333e-05" ixy="0.0" ixz="0.0" iyy="4.2216666666666655e-06" iyz="0.0" izz="1.8770833333333333e-05"/>
    </inertial>
    <collision>
      <origin rpy="1.570796326795 1.570796326795 0" xyz="-0.008 0.014 -0.002"/>
      <geometry>
        <mesh filename="/home/yanxi/curobo/src/curobo/content/assets/robot/iiwa_allegro_description/meshes/reflex/proximal_pad_coll.stl"/>
      </geometry>
    </collision>
  </link>
  <joint name="left_reflex_proximal_3_to_flex" type="fixed">
    <origin rpy="0 0 0" xyz="0.07 0 0.004"/>
    <parent link="left_reflex_proximal_link_3"/>
    <child link="left_reflex_flex_link_3"/>
  </joint>
  <link name="left_reflex_flex_link_3">
    <visual>
      <origin rpy="0 0 0" xyz="0.0005 0 -0.003"/>
      <geometry>
        <box size="0.017 0.014 0.0065"/>
      </geometry>
      <material name="gold">
        <color rgba="0.996078431372549 0.8470588235294118 0.36470588235294116 1"/>
      </material>
    </visual>
    <inertial>
      <origin rpy="0 0 0" xyz="0 0 0"/>
      <mass value="0.01"/>
      <inertia ixx="3.5083333333333334e-07" ixy="0.0" ixz="0.0" iyy="2.0833333333333333e-07" iyz="0.0" izz="1.841666666666667e-07"/>
    </inertial>
    <collision>
      <origin rpy="0 0 0" xyz="0 0 0"/>
      <geometry>
        <box size="0.01 0.01 0.01"/>
      </geometry>
    </collision>
  </link>
  <joint name="left_reflex_flex_to_distal_3" type="fixed">
    <origin rpy="0 0 0" xyz="0 0 0"/>
    <parent link="left_reflex_flex_link_3"/>
    <child link="left_reflex_distal_link_3"/>
  </joint>
  <link name="left_reflex_distal_link_3">
    <visual>
      <origin rpy="3.14159265359 0 0" xyz="-0.077 0.007 0.007"/>
      <geometry>
        <mesh filename="/home/yanxi/curobo/src/curobo/content/assets/robot/iiwa_allegro_description/meshes/reflex/distal.stl"/>
      </geometry>
      <material name="black"/>
    </visual>
    <inertial>
      <origin rpy="3.1459 0 0" xyz="-0.077 0.007 0.007"/>
      <mass value="0.01"/>
      <inertia ixx="2.00175e-05" ixy="0.0" ixz="0.0" iyy="1.5083333333333332e-06" iyz="0.0" izz="1.899083333333333e-05"/>
    </inertial>
    <collision>
      <origin rpy="3.14159265359 0 0" xyz="-0.077 0.007 0.007"/>
      <geometry>
        <mesh filename="/home/yanxi/curobo/src/curobo/content/assets/robot/iiwa_allegro_description/meshes/reflex/distal_coll.stl"/>
      </geometry>
    </collision>
  </link>
  <joint name="left_reflex_distal_3_to_pad" type="fixed">
    <origin rpy="1.570796326795 0 -1.570796326795" xyz="-0.01 0 0.001"/>
    <parent link="left_reflex_distal_link_3"/>
    <child link="left_reflex_distal_pad_link_3"/>
  </joint>
  <link name="left_reflex_distal_pad_link_3">
    <visual>
      <origin rpy="1.570796326795 1.570796326795 0" xyz="-0.00825 0.009 0.057"/>
      <geometry>
        <mesh filename="/home/yanxi/curobo/src/curobo/content/assets/robot/iiwa_allegro_description/meshes/reflex/distal_pad.stl"/>
      </geometry>
      <material name="dark_grey">
        <color rgba="0.2 0.2 0.2 1"/>
      </material>
    </visual>
    <inertial>
      <origin rpy="1.570796326795 1.570796326795 0" xyz="-0.00825 0.009 0.057"/>
      <mass value="0.01"/>
      <inertia ixx="2.00175e-05" ixy="0.0" ixz="0.0" iyy="1.2883333333333332e-06" iyz="0.0" izz="1.8770833333333333e-05"/>
    </inertial>
    <collision>
      <origin rpy="1.570796326795 1.570796326795 0" xyz="-0.00825 0.009 0.057"/>
      <geometry>
        <mesh filename="/home/yanxi/curobo/src/curobo/content/assets/robot/iiwa_allegro_description/meshes/reflex/distal_pad_coll.stl"/>
      </geometry>
    </collision>
  </link>
  <!-- Colors -->
  <gazebo reference="left_reflex_shell_link">
    <material>Gazebo/Black</material>
  </gazebo>
  <gazebo reference="left_reflex_pad_link">
    <material>Gazebo/FlatBlack</material>
  </gazebo>
  <gazebo reference="left_reflex_swivel_link_1">
    <material>Gazebo/Black</material>
  </gazebo>
  <gazebo reference="left_reflex_distal_link_1">
    <material>Gazebo/FlatBlack</material>
  </gazebo>
  <gazebo reference="left_reflex_proximal_link_1">
    <material>Gazebo/FlatBlack</material>
  </gazebo>
  <gazebo reference="left_reflex_distal_pad_link_1">
    <material>Gazebo/FlatBlack</material>
    <mu1>100.0</mu1>
    <mu2>100.0</mu2>
    <minDepth>0.003</minDepth>
  </gazebo>
  <gazebo reference="left_reflex_proximal_pad_link_1">
    <material>Gazebo/FlatBlack</material>
    <mu1>100.0</mu1>
    <mu2>100.0</mu2>
    <minDepth>0.003</minDepth>
  </gazebo>
  <gazebo reference="left_reflex_flex_link_1">
    <material>Gazebo/YellowTransparent</material>
  </gazebo>
  <gazebo reference="left_reflex_swivel_link_2">
    <material>Gazebo/Black</material>
  </gazebo>
  <gazebo reference="left_reflex_distal_link_2">
    <material>Gazebo/FlatBlack</material>
  </gazebo>
  <gazebo reference="left_reflex_proximal_link_2">
    <material>Gazebo/FlatBlack</material>
  </gazebo>
  <gazebo reference="left_reflex_distal_pad_link_2">
    <material>Gazebo/FlatBlack</material>
    <mu1>100.0</mu1>
    <mu2>100.0</mu2>
    <minDepth>0.003</minDepth>
  </gazebo>
  <gazebo reference="left_reflex_proximal_pad_link_2">
    <material>Gazebo/FlatBlack</material>
    <mu1>100.0</mu1>
    <mu2>100.0</mu2>
    <minDepth>0.003</minDepth>
  </gazebo>
  <gazebo reference="left_reflex_flex_link_2">
    <material>Gazebo/YellowTransparent</material>
  </gazebo>
  <gazebo reference="left_reflex_swivel_link_3">
    <material>Gazebo/Black</material>
  </gazebo>
  <gazebo reference="left_reflex_distal_link_3">
    <material>Gazebo/FlatBlack</material>
  </gazebo>
  <gazebo reference="left_reflex_proximal_link_3">
    <material>Gazebo/FlatBlack</material>
  </gazebo>
  <gazebo reference="left_reflex_distal_pad_link_3">
    <material>Gazebo/FlatBlack</material>
    <mu1>100.0</mu1>
    <mu2>100.0</mu2>
    <minDepth>0.003</minDepth>
  </gazebo>
  <gazebo reference="left_reflex_proximal_pad_link_3">
    <material>Gazebo/FlatBlack</material>
    <mu1>100.0</mu1>
    <mu2>100.0</mu2>
    <minDepth>0.003</minDepth>
  </gazebo>
  <gazebo reference="left_reflex_flex_link_3">
    <material>Gazebo/YellowTransparent</material>
  </gazebo>
  <transmission name="left_reflex_preshape_joint_1_transmission">
    <type>transmission_interface/SimpleTransmission</type>
    <joint name="left_reflex_preshape_joint_1">
      <hardwareInterface>hardware_interface/EffortJointInterface</hardwareInterface>
    </joint>
    <actuator name="left_reflex_preshape_joint_1_motor">
      <hardwareInterface>hardware_interface/EffortJointInterface</hardwareInterface>
      <mechanicalReduction>1</mechanicalReduction>
    </actuator>
  </transmission>
  <transmission name="left_reflex_preshape_joint_2_transmission">
    <type>transmission_interface/SimpleTransmission</type>
    <joint name="left_reflex_preshape_joint_2">
      <hardwareInterface>hardware_interface/EffortJointInterface</hardwareInterface>
    </joint>
    <actuator name="left_reflex_preshape_joint_2_motor">
      <hardwareInterface>hardware_interface/EffortJointInterface</hardwareInterface>
      <mechanicalReduction>1</mechanicalReduction>
    </actuator>
  </transmission>
  <transmission name="left_reflex_proximal_joint_1_transmission">
    <type>transmission_interface/SimpleTransmission</type>
    <joint name="left_reflex_proximal_joint_1">
      <hardwareInterface>hardware_interface/EffortJointInterface</hardwareInterface>
    </joint>
    <actuator name="left_reflex_proximal_joint_1_motor">
      <hardwareInterface>hardware_interface/EffortJointInterface</hardwareInterface>
      <mechanicalReduction>1</mechanicalReduction>
    </actuator>
  </transmission>
  <transmission name="left_reflex_proximal_joint_2_transmission">
    <type>transmission_interface/SimpleTransmission</type>
    <joint name="left_reflex_proximal_joint_2">
      <hardwareInterface>hardware_interface/EffortJointInterface</hardwareInterface>
    </joint>
    <actuator name="left_reflex_proximal_joint_2_motor">
      <hardwareInterface>hardware_interface/EffortJointInterface</hardwareInterface>
      <mechanicalReduction>1</mechanicalReduction>
    </actuator>
  </transmission>
  <transmission name="left_reflex_proximal_joint_3_transmission">
    <type>transmission_interface/SimpleTransmission</type>
    <joint name="left_reflex_proximal_joint_3">
      <hardwareInterface>hardware_interface/EffortJointInterface</hardwareInterface>
    </joint>
    <actuator name="left_reflex_proximal_joint_3_motor">
      <hardwareInterface>hardware_interface/EffortJointInterface</hardwareInterface>
      <mechanicalReduction>1</mechanicalReduction>
    </actuator>
  </transmission>
  <!-- Mount + screws -->
  <link name="left_reflex_reflex2_to_iiwa_mount">
    <inertial>
      <origin rpy="0 0 0" xyz="0 0 0"/>
      <mass value="0.064"/>
      <inertia ixx="2.0368000000000002e-05" ixy="0.0" ixz="0.0" iyy="2.0368000000000002e-05" iyz="0.0" izz="3.9200000000000004e-05"/>
    </inertial>
    <visual>
      <origin rpy="0 0 0" xyz="0 0 0"/>
      <geometry>
        <cylinder length="0.012" radius="0.035"/>
      </geometry>
      <material name="black"/>
    </visual>
    <collision>
      <origin rpy="0 0 0" xyz="0 0 0"/>
      <geometry>
        <cylinder length="0.012" radius="0.035"/>
      </geometry>
    </collision>
  </link>
  <!-- Made up value -->
  <link name="left_reflex_reflex2_extra_shell">
    <inertial>
      <origin rpy="0 0 0" xyz="0 0 0"/>
      <mass value="0.01"/>
      <inertia ixx="4.020833333333332e-06" ixy="0.0" ixz="0.0" iyy="4.020833333333332e-06" iyz="0.0" izz="8.000000000000001e-06"/>
    </inertial>
    <visual>
      <origin rpy="0 0 0" xyz="0 0 0"/>
      <geometry>
        <cylinder length="0.005" radius="0.04"/>
      </geometry>
      <material name="black"/>
    </visual>
    <collision>
      <origin rpy="0 0 0" xyz="0 0 0"/>
      <geometry>
        <cylinder length="0.005" radius="0.04"/>
      </geometry>
    </collision>
  </link>
  <joint name="left_iiwa_to_mount" type="fixed">
    <parent link="left_iiwa_link_ee"/>
    <child link="left_reflex_reflex2_to_iiwa_mount"/>
    <origin rpy="0 0 0" xyz="0 0 0.006"/>
  </joint>
  <joint name="left_reflex_mount_to_extra_shell" type="fixed">
    <parent link="left_reflex_reflex2_to_iiwa_mount"/>
    <child link="left_reflex_reflex2_extra_shell"/>
    <origin rpy="0 0 0" xyz="0 0 0.0085"/>
  </joint>
  <joint name="extra_shell_to_left_reflex" type="fixed">
    <parent link="left_reflex_reflex2_extra_shell"/>
    <child link="left_reflex_shell_link"/>
    <origin rpy="0 0 3.141592653589793" xyz="0.014 0 0.0025"/>
  </joint>
  <link name="right_iiwa_table">
    <inertial>
      <origin rpy="0 0 0" xyz="0 0 0"/>
      <mass value="200"/>
      <inertia ixx="0.1" ixy="0" ixz="0" iyy="0.1" iyz="0" izz="0.1"/>
    </inertial>
    <visual>
      <origin rpy="0 0 0" xyz="0 0 0"/>
      <geometry>
        <box size="0.61 0.9125 0.59"/>
      </geometry>
      <material name="table_color">
        <color rgba="0.8235294117647058 0.6666666666666666 0.47058823529411764 1.0"/>
      </material>
    </visual>
    <collision>
      <origin rpy="0 0 0" xyz="0 0 0"/>
      <geometry>
        <box size="0.61 0.9125 0.59"/>
      </geometry>
    </collision>
  </link>
  <gazebo reference="right_iiwa_table">
    <visual>
      <material>
        <ambient>0.8235294117647058 0.6666666666666666 0.47058823529411764 1.0</ambient>
        <diffuse>0.50754 0.50754 0.50754 1.0</diffuse>
        <specular>1 1 1 0</specular>
        <emissive>0.0 0.0 0.0 0.0</emissive>
      </material>
    </visual>
  </gazebo>
  <joint name="world_to_right_table" type="fixed">
    <!-- Change this origin to adjust relative pose of robot tables -->
    <origin rpy="0 0 0" xyz="0 -0.45625 0.295"/>
    <parent link="world"/>
    <child link="right_iiwa_table"/>
  </joint>
  <joint name="right_iiwa_table_to_right_iiwa" type="fixed">
    <origin rpy="0 0 3.141592653589793" xyz="0 0 0.295"/>
    <parent link="right_iiwa_table"/>
    <child link="right_iiwa_link_0"/>
  </joint>
  <link name="right_iiwa_link_0">
    <inertial>
      <origin rpy="0 0 0" xyz="-0.1 0 0.07"/>
      <mass value="5"/>
      <inertia ixx="0.05" ixy="0" ixz="0" iyy="0.06" iyz="0" izz="0.03"/>
    </inertial>
    <visual>
      <origin rpy="0 0 0" xyz="0 0 0"/>
      <geometry>
        <mesh filename="/home/yanxi/curobo/src/curobo/content/assets/robot/iiwa_allegro_description/meshes/iiwa/visual/link_0.dae"/>
      </geometry>
      <material name="Grey"/>
    </visual>
    <collision>
      <origin rpy="0 0 0" xyz="0 0 0"/>
      <geometry>
        <mesh filename="/home/yanxi/curobo/src/curobo/content/assets/robot/iiwa_allegro_description/meshes/iiwa/collision/link_0.stl"/>
      </geometry>
      <material name="Grey"/>
    </collision>
  </link>
  <joint name="right_iiwa_joint_1" type="revolute">
    <parent link="right_iiwa_link_0"/>
    <child link="right_iiwa_link_1"/>
    <origin rpy="0 0 0" xyz="0 0 0.1575"/>
    <axis xyz="0 0 1"/>
    <limit effort="300" lower="-2.9670597283903604" upper="2.9670597283903604" velocity="1.4835298641951802"/>
    <dynamics damping="20"/>
  </joint>
  <link name="right_iiwa_link_1">
    <inertial>
      <origin rpy="0 0 0" xyz="0 -0.03 0.12"/>
      <mass value="4"/>
      <inertia ixx="0.1" ixy="0" ixz="0" iyy="0.09" iyz="0" izz="0.02"/>
    </inertial>
    <visual>
      <origin rpy="0 0 0" xyz="0 0 0"/>
      <geometry>
        <mesh filename="/home/yanxi/curobo/src/curobo/content/assets/robot/iiwa_allegro_description/meshes/iiwa/visual/link_1.dae"/>
      </geometry>
      <material name="Grey"/>
    </visual>
    <collision>
      <origin rpy="0 0 0" xyz="0 0 0"/>
      <geometry>
        <mesh filename="/home/yanxi/curobo/src/curobo/content/assets/robot/iiwa_allegro_description/meshes/iiwa/collision/link_1.stl"/>
      </geometry>
      <material name="Grey"/>
    </collision>
  </link>
  <joint name="right_iiwa_joint_2" type="revolute">
    <parent link="right_iiwa_link_1"/>
    <child link="right_iiwa_link_2"/>
    <origin rpy="1.5707963267948966   0 3.141592653589793" xyz="0 0 0.2025"/>
    <axis xyz="0 0 1"/>
    <limit effort="300" lower="-2.0943951023931953" upper="2.0943951023931953" velocity="1.4835298641951802"/>
    <dynamics damping="20"/>
  </joint>
  <link name="right_iiwa_link_2">
    <inertial>
      <origin rpy="0 0 0" xyz="0.0003 0.059 0.042"/>
      <mass value="4"/>
      <inertia ixx="0.05" ixy="0" ixz="0" iyy="0.018" iyz="0" izz="0.044"/>
    </inertial>
    <visual>
      <origin rpy="0 0 0" xyz="0 0 0"/>
      <geometry>
        <mesh filename="/home/yanxi/curobo/src/curobo/content/assets/robot/iiwa_allegro_description/meshes/iiwa/visual/link_2.dae"/>
      </geometry>
      <material name="Grey"/>
    </visual>
    <collision>
      <origin rpy="0 0 0" xyz="0 0 0"/>
      <geometry>
        <mesh filename="/home/yanxi/curobo/src/curobo/content/assets/robot/iiwa_allegro_description/meshes/iiwa/collision/link_2.stl"/>
      </geometry>
      <material name="Grey"/>
    </collision>
  </link>
  <joint name="right_iiwa_joint_3" type="revolute">
    <parent link="right_iiwa_link_2"/>
    <child link="right_iiwa_link_3"/>
    <origin rpy="1.5707963267948966 0 3.141592653589793" xyz="0 0.2045 0"/>
    <axis xyz="0 0 1"/>
    <limit effort="300" lower="-2.9670597283903604" upper="2.9670597283903604" velocity="1.7453292519943295"/>
    <dynamics damping="20"/>
  </joint>
  <link name="right_iiwa_link_3">
    <inertial>
      <origin rpy="0 0 0" xyz="0 0.03 0.13"/>
      <mass value="3"/>
      <inertia ixx="0.08" ixy="0" ixz="0" iyy="0.075" iyz="0" izz="0.01"/>
    </inertial>
    <visual>
      <origin rpy="0 0 0" xyz="0 0 0"/>
      <geometry>
        <mesh filename="/home/yanxi/curobo/src/curobo/content/assets/robot/iiwa_allegro_description/meshes/iiwa/visual/link_3.dae"/>
      </geometry>
      <material name="Grey"/>
    </visual>
    <collision>
      <origin rpy="0 0 0" xyz="0 0 0"/>
      <geometry>
        <mesh filename="/home/yanxi/curobo/src/curobo/content/assets/robot/iiwa_allegro_description/meshes/iiwa/collision/link_3.stl"/>
      </geometry>
      <material name="Grey"/>
    </collision>
  </link>
  <joint name="right_iiwa_joint_4" type="revolute">
    <parent link="right_iiwa_link_3"/>
    <child link="right_iiwa_link_4"/>
    <origin rpy="1.5707963267948966 0 0" xyz="0 0 0.2155"/>
    <axis xyz="0 0 1"/>
    <limit effort="300" lower="-2.0943951023931953" upper="2.0943951023931953" velocity="1.3089969389957472"/>
    <dynamics damping="20"/>
  </joint>
  <link name="right_iiwa_link_4">
    <inertial>
      <origin rpy="0 0 0" xyz="0 0.067 0.034"/>
      <mass value="2.7"/>
      <inertia ixx="0.03" ixy="0" ixz="0" iyy="0.01" iyz="0" izz="0.029"/>
    </inertial>
    <visual>
      <origin rpy="0 0 0" xyz="0 0 0"/>
      <geometry>
        <mesh filename="/home/yanxi/curobo/src/curobo/content/assets/robot/iiwa_allegro_description/meshes/iiwa/visual/link_4.dae"/>
      </geometry>
      <material name="Grey"/>
    </visual>
    <collision>
      <origin rpy="0 0 0" xyz="0 0 0"/>
      <geometry>
        <mesh filename="/home/yanxi/curobo/src/curobo/content/assets/robot/iiwa_allegro_description/meshes/iiwa/collision/link_4.stl"/>
      </geometry>
      <material name="Grey"/>
    </collision>
  </link>
  <joint name="right_iiwa_joint_5" type="revolute">
    <parent link="right_iiwa_link_4"/>
    <child link="right_iiwa_link_5"/>
    <origin rpy="-1.5707963267948966 3.141592653589793 0" xyz="0 0.1845 0"/>
    <axis xyz="0 0 1"/>
    <limit effort="300" lower="-2.9670597283903604" upper="2.9670597283903604" velocity="2.2689280275926285"/>
    <dynamics damping="20"/>
  </joint>
  <link name="right_iiwa_link_5">
    <inertial>
      <origin rpy="0 0 0" xyz="0.0001 0.021 0.076"/>
      <mass value="1.7"/>
      <inertia ixx="0.02" ixy="0" ixz="0" iyy="0.018" iyz="0" izz="0.005"/>
    </inertial>
    <visual>
      <origin rpy="0 0 0" xyz="0 0 0"/>
      <geometry>
        <mesh filename="/home/yanxi/curobo/src/curobo/content/assets/robot/iiwa_allegro_description/meshes/iiwa/visual/link_5.dae"/>
      </geometry>
      <material name="Grey"/>
    </visual>
    <collision>
      <origin rpy="0 0 0" xyz="0 0 0"/>
      <geometry>
        <mesh filename="/home/yanxi/curobo/src/curobo/content/assets/robot/iiwa_allegro_description/meshes/iiwa/collision/link_5.stl"/>
      </geometry>
      <material name="Grey"/>
    </collision>
  </link>
  <joint name="right_iiwa_joint_6" type="revolute">
    <parent link="right_iiwa_link_5"/>
    <child link="right_iiwa_link_6"/>
    <origin rpy="1.5707963267948966 0 0" xyz="0 0 0.2155"/>
    <axis xyz="0 0 1"/>
    <limit effort="300" lower="-2.0943951023931953" upper="2.0943951023931953" velocity="2.356194490192345"/>
    <dynamics damping="20"/>
  </joint>
  <link name="right_iiwa_link_6">
    <inertial>
      <origin rpy="0 0 0" xyz="0 0.0006 0.0004"/>
      <mass value="1.8"/>
      <inertia ixx="0.005" ixy="0" ixz="0" iyy="0.0036" iyz="0" izz="0.0047"/>
    </inertial>
    <visual>
      <origin rpy="0 0 0" xyz="0 0 0"/>
      <geometry>
        <mesh filename="/home/yanxi/curobo/src/curobo/content/assets/robot/iiwa_allegro_description/meshes/iiwa/visual/link_6.dae"/>
      </geometry>
      <material name="Grey"/>
    </visual>
    <collision>
      <origin rpy="0 0 0" xyz="0 0 0"/>
      <geometry>
        <mesh filename="/home/yanxi/curobo/src/curobo/content/assets/robot/iiwa_allegro_description/meshes/iiwa/collision/link_6.stl"/>
      </geometry>
      <material name="Grey"/>
    </collision>
  </link>
  <joint name="right_iiwa_joint_7" type="revolute">
    <parent link="right_iiwa_link_6"/>
    <child link="right_iiwa_link_7"/>
    <origin rpy="-1.5707963267948966 3.141592653589793 0" xyz="0 0.081 0"/>
    <axis xyz="0 0 1"/>
    <limit effort="300" lower="-3.0543261909900763" upper="3.0543261909900763" velocity="2.356194490192345"/>
    <dynamics damping="20"/>
  </joint>
  <link name="right_iiwa_link_7">
    <inertial>
      <origin rpy="0 0 0" xyz="0 0 0.02"/>
      <mass value="0.3"/>
      <inertia ixx="0.001" ixy="0" ixz="0" iyy="0.001" iyz="0" izz="0.001"/>
    </inertial>
    <visual>
      <origin rpy="0 0 0" xyz="0 0 0"/>
      <geometry>
        <mesh filename="/home/yanxi/curobo/src/curobo/content/assets/robot/iiwa_allegro_description/meshes/iiwa/visual/link_7.dae"/>
      </geometry>
      <material name="Grey"/>
    </visual>
    <collision>
      <origin rpy="0 0 0" xyz="0 0 0"/>
      <geometry>
        <mesh filename="/home/yanxi/curobo/src/curobo/content/assets/robot/iiwa_allegro_description/meshes/iiwa/collision/link_7.stl"/>
      </geometry>
      <material name="Grey"/>
    </collision>
  </link>
  <joint name="right_iiwa_joint_ee" type="fixed">
    <parent link="right_iiwa_link_7"/>
    <child link="right_iiwa_link_ee"/>
    <origin rpy="0 0 0" xyz="0 0 0.045"/>
  </joint>
  <link name="right_iiwa_link_ee">
    </link>
  <transmission name="right_iiwa_trans_1">
    <type>transmission_interface/SimpleTransmission</type>
    <joint name="right_iiwa_joint_1">
      <hardwareInterface>hardware_interface/EffortJointInterface</hardwareInterface>
    </joint>
    <actuator name="right_iiwa_motor_1">
      <hardwareInterface>hardware_interface/EffortJointInterface</hardwareInterface>
      <mechanicalReduction>1</mechanicalReduction>
    </actuator>
  </transmission>
  <transmission name="right_iiwa_trans_2">
    <type>transmission_interface/SimpleTransmission</type>
    <joint name="right_iiwa_joint_2">
      <hardwareInterface>hardware_interface/EffortJointInterface</hardwareInterface>
    </joint>
    <actuator name="right_iiwa_motor_2">
      <hardwareInterface>hardware_interface/EffortJointInterface</hardwareInterface>
      <mechanicalReduction>1</mechanicalReduction>
    </actuator>
  </transmission>
  <transmission name="right_iiwa_trans_3">
    <type>transmission_interface/SimpleTransmission</type>
    <joint name="right_iiwa_joint_3">
      <hardwareInterface>hardware_interface/EffortJointInterface</hardwareInterface>
    </joint>
    <actuator name="right_iiwa_motor_3">
      <hardwareInterface>hardware_interface/EffortJointInterface</hardwareInterface>
      <mechanicalReduction>1</mechanicalReduction>
    </actuator>
  </transmission>
  <transmission name="right_iiwa_trans_4">
    <type>transmission_interface/SimpleTransmission</type>
    <joint name="right_iiwa_joint_4">
      <hardwareInterface>hardware_interface/EffortJointInterface</hardwareInterface>
    </joint>
    <actuator name="right_iiwa_motor_4">
      <hardwareInterface>hardware_interface/EffortJointInterface</hardwareInterface>
      <mechanicalReduction>1</mechanicalReduction>
    </actuator>
  </transmission>
  <transmission name="right_iiwa_trans_5">
    <type>transmission_interface/SimpleTransmission</type>
    <joint name="right_iiwa_joint_5">
      <hardwareInterface>hardware_interface/EffortJointInterface</hardwareInterface>
    </joint>
    <actuator name="right_iiwa_motor_5">
      <hardwareInterface>hardware_interface/EffortJointInterface</hardwareInterface>
      <mechanicalReduction>1</mechanicalReduction>
    </actuator>
  </transmission>
  <transmission name="right_iiwa_trans_6">
    <type>transmission_interface/SimpleTransmission</type>
    <joint name="right_iiwa_joint_6">
      <hardwareInterface>hardware_interface/EffortJointInterface</hardwareInterface>
    </joint>
    <actuator name="right_iiwa_motor_6">
      <hardwareInterface>hardware_interface/EffortJointInterface</hardwareInterface>
      <mechanicalReduction>1</mechanicalReduction>
    </actuator>
  </transmission>
  <transmission name="right_iiwa_trans_7">
    <type>transmission_interface/SimpleTransmission</type>
    <joint name="right_iiwa_joint_7">
      <hardwareInterface>hardware_interface/EffortJointInterface</hardwareInterface>
    </joint>
    <actuator name="right_iiwa_motor_7">
      <hardwareInterface>hardware_interface/EffortJointInterface</hardwareInterface>
      <mechanicalReduction>1</mechanicalReduction>
    </actuator>
  </transmission>
  <!-- TODO these selfCollide tags are necessary for the arms to be able to collide with
           each other, which definitely seems necessary for bimanual as you want to render
           when one arm collides with other. However, there has been some problem with controlling
           any hands attached to robots when these tags are enabled. I haven't yet tried also
           adding the tags to the hands, which should be done anyways, so give that a shot
           and see if hand can be controlled then with all selfCollide tags active on whole model. -->
  <gazebo reference="right_iiwa_link_0">
    <material>Gazebo/Grey</material>
    <mu1>0.2</mu1>
    <mu2>0.2</mu2>
    <!-- <selfCollide>true</selfCollide> -->
  </gazebo>
  <gazebo reference="right_iiwa_link_1">
    <material>Gazebo/Grey</material>
    <mu1>0.2</mu1>
    <mu2>0.2</mu2>
    <!-- <selfCollide>true</selfCollide> -->
  </gazebo>
  <gazebo reference="right_iiwa_link_2">
    <material>Gazebo/Grey</material>
    <mu1>0.2</mu1>
    <mu2>0.2</mu2>
    <!-- <selfCollide>true</selfCollide> -->
  </gazebo>
  <gazebo reference="right_iiwa_link_3">
    <material>Gazebo/Grey</material>
    <mu1>0.2</mu1>
    <mu2>0.2</mu2>
    <!-- <selfCollide>true</selfCollide> -->
  </gazebo>
  <gazebo reference="right_iiwa_link_4">
    <material>Gazebo/Grey</material>
    <mu1>0.2</mu1>
    <mu2>0.2</mu2>
    <!-- <selfCollide>true</selfCollide> -->
  </gazebo>
  <gazebo reference="right_iiwa_link_5">
    <material>Gazebo/Grey</material>
    <mu1>0.2</mu1>
    <mu2>0.2</mu2>
    <!-- <selfCollide>true</selfCollide> -->
  </gazebo>
  <gazebo reference="right_iiwa_link_6">
    <material>Gazebo/Grey</material>
    <mu1>0.2</mu1>
    <mu2>0.2</mu2>
    <!-- <selfCollide>true</selfCollide> -->
  </gazebo>
  <gazebo reference="right_iiwa_link_7">
    <material>Gazebo/Grey</material>
    <mu1>0.2</mu1>
    <mu2>0.2</mu2>
    <!-- <selfCollide>true</selfCollide> -->
  </gazebo>
  <link name="right_robotiq_base_link">
    <inertial>
      <origin rpy="0 0 0" xyz="8.625E-08 -4.6583E-06 0.03145"/>
      <mass value="0.22652"/>
      <inertia ixx="0.00020005" ixy="-4.2442E-10" ixz="-2.9069E-10" iyy="0.00017832" iyz="-3.4402E-08" izz="0.00013478"/>
    </inertial>
    <visual>
      <origin rpy="0 0 0" xyz="0 0 0"/>
      <geometry>
        <mesh filename="/home/yanxi/curobo/src/curobo/content/assets/robot/iiwa_allegro_description/meshes/robotiq/visual/robotiq_arg2f_base_link.stl"/>
      </geometry>
      <material name="">
        <color rgba="0.1 0.1 0.1 1"/>
      </material>
    </visual>
    <collision>
      <origin rpy="0 0 0" xyz="0 0 0"/>
      <geometry>
        <mesh filename="/home/yanxi/curobo/src/curobo/content/assets/robot/iiwa_allegro_description/meshes/robotiq/collision/robotiq_arg2f_base_link.stl"/>
      </geometry>
    </collision>
  </link>
  <joint name="right_robotiq_palm_joint" type="fixed">
    <origin rpy="0 -1.570796326795 -1.570796326795" xyz="0 0 0"/>
    <parent link="right_robotiq_base_link"/>
    <child link="right_robotiq_palm_link"/>
    <axis xyz="0 0 0"/>
  </joint>
  <link name="right_robotiq_palm_link"/>
  <!-- A dummy link to define the end-effector frame -->
  <link name="right_robotiq_left_outer_knuckle">
    <inertial>
      <origin rpy="0 0 0" xyz="-0.000200000000003065 0.0199435877845359 0.0292245259211331"/>
      <mass value="0.00853198276973456"/>
      <inertia ixx="2.89328108496468E-06" ixy="-1.57935047237397E-19" ixz="-1.93980378593255E-19" iyy="1.86719750325683E-06" iyz="-1.21858577871576E-06" izz="1.21905238907251E-06"/>
    </inertial>
    <visual>
      <origin rpy="0 0 0" xyz="0 0 0"/>
      <geometry>
        <mesh filename="/home/yanxi/curobo/src/curobo/content/assets/robot/iiwa_allegro_description/meshes/robotiq/visual/robotiq_arg2f_140_outer_knuckle.stl"/>
      </geometry>
      <material name="">
        <color rgba="0.792156862745098 0.819607843137255 0.933333333333333 1"/>
      </material>
    </visual>
    <collision>
      <origin rpy="0 0 0" xyz="0 0 0"/>
      <geometry>
        <mesh filename="/home/yanxi/curobo/src/curobo/content/assets/robot/iiwa_allegro_description/meshes/robotiq/collision/robotiq_arg2f_140_outer_knuckle.stl"/>
      </geometry>
    </collision>
  </link>
  <link name="right_robotiq_left_outer_finger">
    <inertial>
      <origin rpy="0 0 0" xyz="0.00030115855001899 0.0373907951953854 -0.0208027427000385"/>
      <mass value="0.022614240507152"/>
      <inertia ixx="1.52518312458174E-05" ixy="9.76583423954399E-10" ixz="-5.43838577022588E-10" iyy="6.17694243867776E-06" iyz="6.78636130740228E-06" izz="1.16494917907219E-05"/>
    </inertial>
    <visual>
      <origin rpy="0 0 0" xyz="0 0 0"/>
      <geometry>
        <mesh filename="/home/yanxi/curobo/src/curobo/content/assets/robot/iiwa_allegro_description/meshes/robotiq/visual/robotiq_arg2f_140_outer_finger.stl"/>
      </geometry>
      <material name="">
        <color rgba="0.1 0.1 0.1 1"/>
      </material>
    </visual>
    <collision>
      <origin rpy="0 0 0" xyz="0 0 0"/>
      <geometry>
        <mesh filename="/home/yanxi/curobo/src/curobo/content/assets/robot/iiwa_allegro_description/meshes/robotiq/collision/robotiq_arg2f_140_outer_finger.stl"/>
      </geometry>
    </collision>
  </link>
  <link name="right_robotiq_left_inner_finger">
    <inertial>
      <origin rpy="0 0 0" xyz="0.000299999999999317 0.0160078233491243 -0.0136945669206257"/>
      <mass value="0.0104003125914103"/>
      <inertia ixx="2.71909453810972E-06" ixy="1.35402465472579E-21" ixz="-7.1817349065269E-22" iyy="7.69100314106116E-07" iyz="6.74715432769696E-07" izz="2.30315190420171E-06"/>
    </inertial>
    <visual>
      <origin rpy="0 0 0" xyz="0 0 0"/>
      <geometry>
        <mesh filename="/home/yanxi/curobo/src/curobo/content/assets/robot/iiwa_allegro_description/meshes/robotiq/visual/robotiq_arg2f_140_inner_finger.stl"/>
      </geometry>
      <material name="">
        <color rgba="0.1 0.1 0.1 1"/>
      </material>
    </visual>
    <collision>
      <origin rpy="0 0 0" xyz="0 0 0"/>
      <geometry>
        <mesh filename="/home/yanxi/curobo/src/curobo/content/assets/robot/iiwa_allegro_description/meshes/robotiq/collision/robotiq_arg2f_140_inner_finger.stl"/>
      </geometry>
    </collision>
  </link>
  <link name="right_robotiq_left_inner_finger_pad">
    <visual>
      <origin rpy="0 0 0" xyz="0 0 0"/>
      <geometry>
        <box size="0.027 0.065 0.0075"/>
      </geometry>
      <material name="">
        <color rgba="0.9 0.9 0.9 1"/>
      </material>
    </visual>
    <collision>
      <origin rpy="0 0 0" xyz="0 0 0"/>
      <geometry>
        <box size="0.03 0.07 0.0075"/>
      </geometry>
      <material name="">
        <color rgba="0.9 0.0 0.0 1"/>
      </material>
    </collision>
  </link>
  <link name="right_robotiq_left_inner_knuckle">
    <inertial>
      <origin rpy="0 0 0" xyz="0.000123011831763771 0.0507850843201817 0.00103968640075166"/>
      <mass value="0.0271177346495152"/>
      <inertia ixx="2.61910379223783E-05" ixy="-2.43616858946494E-07" ixz="-6.37789906117123E-09" iyy="2.8270243746167E-06" iyz="-5.37200748039765E-07" izz="2.83695868220296E-05"/>
    </inertial>
    <visual>
      <origin rpy="0 0 0" xyz="0 0 0"/>
      <geometry>
        <mesh filename="/home/yanxi/curobo/src/curobo/content/assets/robot/iiwa_allegro_description/meshes/robotiq/visual/robotiq_arg2f_140_inner_knuckle.stl"/>
      </geometry>
      <material name="">
        <color rgba="0.1 0.1 0.1 1"/>
      </material>
    </visual>
    <collision>
      <origin rpy="0 0 0" xyz="0 0 0"/>
      <geometry>
        <mesh filename="/home/yanxi/curobo/src/curobo/content/assets/robot/iiwa_allegro_description/meshes/robotiq/collision/robotiq_arg2f_140_inner_knuckle.stl"/>
      </geometry>
    </collision>
  </link>
  <link name="right_robotiq_right_outer_knuckle">
    <inertial>
      <origin rpy="0 0 0" xyz="-0.000200000000003065 0.0199435877845359 0.0292245259211331"/>
      <mass value="0.00853198276973456"/>
      <inertia ixx="2.89328108496468E-06" ixy="-1.57935047237397E-19" ixz="-1.93980378593255E-19" iyy="1.86719750325683E-06" iyz="-1.21858577871576E-06" izz="1.21905238907251E-06"/>
    </inertial>
    <visual>
      <origin rpy="0 0 0" xyz="0 0 0"/>
      <geometry>
        <mesh filename="/home/yanxi/curobo/src/curobo/content/assets/robot/iiwa_allegro_description/meshes/robotiq/visual/robotiq_arg2f_140_outer_knuckle.stl"/>
      </geometry>
      <material name="">
        <color rgba="0.792156862745098 0.819607843137255 0.933333333333333 1"/>
      </material>
    </visual>
    <collision>
      <origin rpy="0 0 0" xyz="0 0 0"/>
      <geometry>
        <mesh filename="/home/yanxi/curobo/src/curobo/content/assets/robot/iiwa_allegro_description/meshes/robotiq/collision/robotiq_arg2f_140_outer_knuckle.stl"/>
      </geometry>
    </collision>
  </link>
  <link name="right_robotiq_right_outer_finger">
    <inertial>
      <origin rpy="0 0 0" xyz="0.00030115855001899 0.0373907951953854 -0.0208027427000385"/>
      <mass value="0.022614240507152"/>
      <inertia ixx="1.52518312458174E-05" ixy="9.76583423954399E-10" ixz="-5.43838577022588E-10" iyy="6.17694243867776E-06" iyz="6.78636130740228E-06" izz="1.16494917907219E-05"/>
    </inertial>
    <visual>
      <origin rpy="0 0 0" xyz="0 0 0"/>
      <geometry>
        <mesh filename="/home/yanxi/curobo/src/curobo/content/assets/robot/iiwa_allegro_description/meshes/robotiq/visual/robotiq_arg2f_140_outer_finger.stl"/>
      </geometry>
      <material name="">
        <color rgba="0.1 0.1 0.1 1"/>
      </material>
    </visual>
    <collision>
      <origin rpy="0 0 0" xyz="0 0 0"/>
      <geometry>
        <mesh filename="/home/yanxi/curobo/src/curobo/content/assets/robot/iiwa_allegro_description/meshes/robotiq/collision/robotiq_arg2f_140_outer_finger.stl"/>
      </geometry>
    </collision>
  </link>
  <link name="right_robotiq_right_inner_finger">
    <inertial>
      <origin rpy="0 0 0" xyz="0.000299999999999317 0.0160078233491243 -0.0136945669206257"/>
      <mass value="0.0104003125914103"/>
      <inertia ixx="2.71909453810972E-06" ixy="1.35402465472579E-21" ixz="-7.1817349065269E-22" iyy="7.69100314106116E-07" iyz="6.74715432769696E-07" izz="2.30315190420171E-06"/>
    </inertial>
    <visual>
      <origin rpy="0 0 0" xyz="0 0 0"/>
      <geometry>
        <mesh filename="/home/yanxi/curobo/src/curobo/content/assets/robot/iiwa_allegro_description/meshes/robotiq/visual/robotiq_arg2f_140_inner_finger.stl"/>
      </geometry>
      <material name="">
        <color rgba="0.1 0.1 0.1 1"/>
      </material>
    </visual>
    <collision>
      <origin rpy="0 0 0" xyz="0 0 0"/>
      <geometry>
        <mesh filename="/home/yanxi/curobo/src/curobo/content/assets/robot/iiwa_allegro_description/meshes/robotiq/collision/robotiq_arg2f_140_inner_finger.stl"/>
      </geometry>
    </collision>
  </link>
  <link name="right_robotiq_right_inner_finger_pad">
    <visual>
      <origin rpy="0 0 0" xyz="0 0 0"/>
      <geometry>
        <box size="0.027 0.065 0.0075"/>
      </geometry>
      <material name="">
        <color rgba="0.9 0.9 0.9 1"/>
      </material>
    </visual>
    <collision>
      <origin rpy="0 0 0" xyz="0 0 0"/>
      <geometry>
        <box size="0.03 0.07 0.0075"/>
      </geometry>
      <material name="">
        <color rgba="0.9 0.0 0.0 1"/>
      </material>
    </collision>
  </link>
  <link name="right_robotiq_right_inner_knuckle">
    <inertial>
      <origin rpy="0 0 0" xyz="0.000123011831763771 0.0507850843201817 0.00103968640075166"/>
      <mass value="0.0271177346495152"/>
      <inertia ixx="2.61910379223783E-05" ixy="-2.43616858946494E-07" ixz="-6.37789906117123E-09" iyy="2.8270243746167E-06" iyz="-5.37200748039765E-07" izz="2.83695868220296E-05"/>
    </inertial>
    <visual>
      <origin rpy="0 0 0" xyz="0 0 0"/>
      <geometry>
        <mesh filename="/home/yanxi/curobo/src/curobo/content/assets/robot/iiwa_allegro_description/meshes/robotiq/visual/robotiq_arg2f_140_inner_knuckle.stl"/>
      </geometry>
      <material name="">
        <color rgba="0.1 0.1 0.1 1"/>
      </material>
    </visual>
    <collision>
      <origin rpy="0 0 0" xyz="0 0 0"/>
      <geometry>
        <mesh filename="/home/yanxi/curobo/src/curobo/content/assets/robot/iiwa_allegro_description/meshes/robotiq/collision/robotiq_arg2f_140_inner_knuckle.stl"/>
      </geometry>
    </collision>
  </link>
  <joint name="right_robotiq_finger_joint" type="revolute">
    <origin rpy="2.2957963267948966 0 0" xyz="0 -0.030601 0.054905"/>
    <parent link="right_robotiq_base_link"/>
    <child link="right_robotiq_left_outer_knuckle"/>
    <axis xyz="-1 0 0"/>
    <limit effort="1000" lower="0" upper="0.7" velocity="2.0"/>
  </joint>
  <joint name="right_robotiq_left_outer_finger_joint" type="fixed">
    <origin rpy="0 0 0" xyz="0 0.01821998610742 0.0260018192872234"/>
    <parent link="right_robotiq_left_outer_knuckle"/>
    <child link="right_robotiq_left_outer_finger"/>
    <axis xyz="1 0 0"/>
  </joint>
  <joint name="right_robotiq_left_inner_knuckle_joint" type="revolute">
    <origin rpy="2.2957963267948966 0 0.0" xyz="0 -0.0127 0.06142"/>
    <parent link="right_robotiq_base_link"/>
    <child link="right_robotiq_left_inner_knuckle"/>
    <axis xyz="1 0 0"/>
    <limit effort="1000" lower="0" upper="0.8757" velocity="2.0"/>
    <mimic joint="right_robotiq_finger_joint" multiplier="-1" offset="0"/>
  </joint>
  <joint name="right_robotiq_left_inner_finger_joint" type="revolute">
    <origin rpy="-0.725 0 0" xyz="0 0.0817554015893473 -0.0282203446692936"/>
    <parent link="right_robotiq_left_outer_finger"/>
    <child link="right_robotiq_left_inner_finger"/>
    <axis xyz="1 0 0"/>
    <limit effort="1000" lower="0" upper="0.8757" velocity="2.0"/>
    <mimic joint="right_robotiq_finger_joint" multiplier="1" offset="0"/>
  </joint>
  <joint name="right_robotiq_left_inner_finger_pad_joint" type="fixed">
    <origin rpy="0 0 0" xyz="0 0.0457554015893473 -0.0272203446692936"/>
    <parent link="right_robotiq_left_inner_finger"/>
    <child link="right_robotiq_left_inner_finger_pad"/>
    <axis xyz="0 0 1"/>
  </joint>
  <joint name="right_robotiq_right_outer_knuckle_joint" type="revolute">
    <origin rpy="2.2957963267948966 0 3.141592653589793" xyz="0 0.030601 0.054905"/>
    <parent link="right_robotiq_base_link"/>
    <child link="right_robotiq_right_outer_knuckle"/>
    <axis xyz="1 0 0"/>
    <limit effort="1000" lower="0" upper="0.725" velocity="2.0"/>
    <mimic joint="right_robotiq_finger_joint" multiplier="-1" offset="0"/>
  </joint>
  <joint name="right_robotiq_right_outer_finger_joint" type="fixed">
    <origin rpy="0 0 0" xyz="0 0.01821998610742 0.0260018192872234"/>
    <parent link="right_robotiq_right_outer_knuckle"/>
    <child link="right_robotiq_right_outer_finger"/>
    <axis xyz="1 0 0"/>
  </joint>
  <joint name="right_robotiq_right_inner_knuckle_joint" type="revolute">
    <origin rpy="2.2957963267948966 0 -3.141592653589793" xyz="0 0.0127 0.06142"/>
    <parent link="right_robotiq_base_link"/>
    <child link="right_robotiq_right_inner_knuckle"/>
    <axis xyz="1 0 0"/>
    <limit effort="1000" lower="0" upper="0.8757" velocity="2.0"/>
    <mimic joint="right_robotiq_finger_joint" multiplier="-1" offset="0"/>
  </joint>
  <joint name="right_robotiq_right_inner_finger_joint" type="revolute">
    <origin rpy="-0.725 0 0" xyz="0 0.0817554015893473 -0.0282203446692936"/>
    <parent link="right_robotiq_right_outer_finger"/>
    <child link="right_robotiq_right_inner_finger"/>
    <axis xyz="1 0 0"/>
    <limit effort="1000" lower="0" upper="0.8757" velocity="2.0"/>
    <mimic joint="right_robotiq_finger_joint" multiplier="1" offset="0"/>
  </joint>
  <joint name="right_robotiq_right_inner_finger_pad_joint" type="fixed">
    <origin rpy="0 0 0" xyz="0 0.0457554015893473 -0.0272203446692936"/>
    <parent link="right_robotiq_right_inner_finger"/>
    <child link="right_robotiq_right_inner_finger_pad"/>
    <axis xyz="0 0 1"/>
  </joint>
  <transmission name="right_robotiq_finger_joint_trans">
    <type>transmission_interface/SimpleTransmission</type>
    <joint name="right_robotiq_finger_joint">
      <hardwareInterface>PositionJointInterface</hardwareInterface>
    </joint>
    <actuator name="right_robotiq_finger_joint_motor">
      <mechanicalReduction>1</mechanicalReduction>
    </actuator>
  </transmission>
  <!-- Mount + screws -->
  <link name="right_robotiq_to_iiwa_mount">
    <inertial>
      <origin rpy="0 0 0" xyz="0 0 0"/>
      <mass value="0.064"/>
      <inertia ixx="2.0368000000000002e-05" ixy="0.0" ixz="0.0" iyy="2.0368000000000002e-05" iyz="0.0" izz="3.9200000000000004e-05"/>
    </inertial>
    <visual>
      <origin rpy="0 0 0" xyz="0 0 0"/>
      <geometry>
        <cylinder length="0.012" radius="0.035"/>
      </geometry>
      <material name="black"/>
    </visual>
    <collision>
      <origin rpy="0 0 0" xyz="0 0 0"/>
      <geometry>
        <cylinder length="0.012" radius="0.035"/>
      </geometry>
    </collision>
  </link>
  <joint name="right_iiwa_to_mount" type="fixed">
    <parent link="right_iiwa_link_ee"/>
    <child link="right_robotiq_to_iiwa_mount"/>
    <origin rpy="0 0 3.141592653589793" xyz="0 0 0.006"/>
  </joint>
  <joint name="right_robotiq_mount_to_base_link" type="fixed">
    <parent link="right_robotiq_to_iiwa_mount"/>
    <child link="right_robotiq_base_link"/>
    <origin rpy="0 0 1.5708" xyz="0 0 0.006"/>
  </joint>
  <!-- ROS Control -->
  <gazebo>
    <plugin filename="libgazebo_ros_control.so" name="gazebo_ros_control">
      <!-- This tag gets rid of an error that popped up in version 8.6 -->
      <legacyModeNS>true</legacyModeNS>
    </plugin>
  </gazebo>
  <link name="right_robotiq_grasp_frame">
    <inertial>
      <!-- Dummy inertial parameters to avoid link lumping-->
      <mass value="0.01"/>
      <inertia ixx="0.0001" ixy="0.0" ixz="0.0" iyy="0.0001" iyz="0.0" izz="0.0001"/>
      <origin rpy="0 0 0" xyz="0 0 0"/>
    </inertial>
  </link>
  <joint name="grasp_joint" type="fixed">
    <origin rpy="0 0 0.0" xyz="0 0 0.2"/>
    <axis xyz="0 0 1"/>
    <parent link="right_robotiq_to_iiwa_mount"/>
    <child link="right_robotiq_grasp_frame"/>
  </joint>
</robot>
