<?xml version="1.0" encoding="utf-8"?>
<!-- =================================================================================== -->
<!-- |    This document was autogenerated by xacro from robots/iiwa.robot.xacro        | -->
<!-- |    EDITING THIS FILE BY HAND IS NOT RECOMMENDED                                 | -->
<!-- =================================================================================== -->
<robot name="iiwa">
  <!-- ==================================================================================== -->
  <!-- ==================================================================================== -->
  <!-- END effort_transmission macro -->
  <!-- ======================================================================================= -->
  <!--   MATERIALS                                                                             -->
  <!-- ======================================================================================= -->
  <material name="Grey">
    <color rgba="0.7 0.7 0.7 1.0"/>
  </material>
  <link name="world"/>
  <link name="robot_table_link">
    <inertial>
      <origin rpy="0 0 0" xyz="0 0 0"/>
      <mass value="200"/>
      <inertia ixx="0.1" ixy="0" ixz="0" iyy="0.1" iyz="0" izz="0.1"/>
    </inertial>
    <visual>
      <origin rpy="0 0 0" xyz="0 0 0"/>
      <geometry>
        <box size="0.612 0.9144 0.6"/>
      </geometry>
      <material name="table_color">
        <mesh filename="/home/yanxi/curobo/src/curobo/content/assets/robot/iiwa_allegro_description/meshes/kuka/visual/robot_table_link.dae"/>
      </material>
    </visual>
    <collision>
      <origin rpy="0 0 0" xyz="0 0 0"/>
      <geometry>
        <mesh filename="/home/yanxi/curobo/src/curobo/content/assets/robot/iiwa_allegro_description/meshes/kuka/collision/robot_table_link.stl"/>
      </geometry>
    </collision>
  </link>
  <gazebo reference="robot_table_link">
    <material>Gazebo/DarkGrey</material>
  </gazebo>
  <joint name="world_to_table" type="fixed">
    <parent link="world"/>
    <child link="robot_table_link"/>
    <origin rpy="0 0 0" xyz="0 0 0.3"/>
  </joint>
  <joint name="robot_table_link_to_iiwa" type="fixed">
    <origin rpy="0 0 0" xyz="0 0 0.3"/>
    <parent link="robot_table_link"/>
    <child link="iiwa_link_0"/>
  </joint>
  <link name="iiwa_link_0">
    <inertial>
      <origin rpy="0 0 0" xyz="-0.1 0 0.07"/>
      <mass value="5"/>
      <inertia ixx="0.05" ixy="0" ixz="0" iyy="0.06" iyz="0" izz="0.03"/>
    </inertial>
    <visual>
      <origin rpy="0 0 0" xyz="0 0 0"/>
      <geometry>
        <mesh filename="/home/yanxi/curobo/src/curobo/content/assets/robot/iiwa_allegro_description/meshes/kuka/visual/link_0.dae"/>
      </geometry>
      <material name="Grey"/>
    </visual>
    <collision>
      <origin rpy="0 0 0" xyz="0 0 0"/>
      <geometry>
        <mesh filename="/home/yanxi/curobo/src/curobo/content/assets/robot/iiwa_allegro_description/meshes/kuka/collision/link_0.stl"/>
      </geometry>
      <material name="Grey"/>
    </collision>
  </link>
  <joint name="iiwa_joint_1" type="revolute">
    <parent link="iiwa_link_0"/>
    <child link="iiwa_link_1"/>
    <origin rpy="0 0 0" xyz="0 0 0.1575"/>
    <axis xyz="0 0 1"/>
    <limit effort="300" lower="-2.96705972839" upper="2.96705972839" velocity="1.4835298642"/>
    <dynamics damping="20"/>
  </joint>
  <link name="iiwa_link_1">
    <inertial>
      <origin rpy="0 0 0" xyz="0 -0.03 0.12"/>
      <mass value="4"/>
      <inertia ixx="0.1" ixy="0" ixz="0" iyy="0.09" iyz="0" izz="0.02"/>
    </inertial>
    <visual>
      <origin rpy="0 0 0" xyz="0 0 0"/>
      <geometry>
        <mesh filename="/home/yanxi/curobo/src/curobo/content/assets/robot/iiwa_allegro_description/meshes/kuka/visual/link_1.dae"/>
      </geometry>
      <material name="Grey"/>
    </visual>
    <collision>
      <origin rpy="0 0 0" xyz="0 0 0"/>
      <geometry>
        <mesh filename="/home/yanxi/curobo/src/curobo/content/assets/robot/iiwa_allegro_description/meshes/kuka/collision/link_1.stl"/>
      </geometry>
      <material name="Grey"/>
    </collision>
  </link>
  <joint name="iiwa_joint_2" type="revolute">
    <parent link="iiwa_link_1"/>
    <child link="iiwa_link_2"/>
    <origin rpy="1.57079632679   0 3.14159265359" xyz="0 0 0.2025"/>
    <axis xyz="0 0 1"/>
    <limit effort="300" lower="-2.09439510239" upper="2.09439510239" velocity="1.4835298642"/>
    <dynamics damping="20"/>
  </joint>
  <link name="iiwa_link_2">
    <inertial>
      <origin rpy="0 0 0" xyz="0.0003 0.059 0.042"/>
      <mass value="4"/>
      <inertia ixx="0.05" ixy="0" ixz="0" iyy="0.018" iyz="0" izz="0.044"/>
    </inertial>
    <visual>
      <origin rpy="0 0 0" xyz="0 0 0"/>
      <geometry>
        <mesh filename="/home/yanxi/curobo/src/curobo/content/assets/robot/iiwa_allegro_description/meshes/kuka/visual/link_2.dae"/>
      </geometry>
      <material name="Grey"/>
    </visual>
    <collision>
      <origin rpy="0 0 0" xyz="0 0 0"/>
      <geometry>
        <mesh filename="/home/yanxi/curobo/src/curobo/content/assets/robot/iiwa_allegro_description/meshes/kuka/collision/link_2.stl"/>
      </geometry>
      <material name="Grey"/>
    </collision>
  </link>
  <joint name="iiwa_joint_3" type="revolute">
    <parent link="iiwa_link_2"/>
    <child link="iiwa_link_3"/>
    <origin rpy="1.57079632679 0 3.14159265359" xyz="0 0.2045 0"/>
    <axis xyz="0 0 1"/>
    <limit effort="300" lower="-2.96705972839" upper="2.96705972839" velocity="1.74532925199"/>
    <dynamics damping="20"/>
  </joint>
  <link name="iiwa_link_3">
    <inertial>
      <origin rpy="0 0 0" xyz="0 0.03 0.13"/>
      <mass value="3"/>
      <inertia ixx="0.08" ixy="0" ixz="0" iyy="0.075" iyz="0" izz="0.01"/>
    </inertial>
    <visual>
      <origin rpy="0 0 0" xyz="0 0 0"/>
      <geometry>
        <mesh filename="/home/yanxi/curobo/src/curobo/content/assets/robot/iiwa_allegro_description/meshes/kuka/visual/link_3.dae"/>
      </geometry>
      <material name="Grey"/>
    </visual>
    <collision>
      <origin rpy="0 0 0" xyz="0 0 0"/>
      <geometry>
        <mesh filename="/home/yanxi/curobo/src/curobo/content/assets/robot/iiwa_allegro_description/meshes/kuka/collision/link_3.stl"/>
      </geometry>
      <material name="Grey"/>
    </collision>
  </link>
  <joint name="iiwa_joint_4" type="revolute">
    <parent link="iiwa_link_3"/>
    <child link="iiwa_link_4"/>
    <origin rpy="1.57079632679 0 0" xyz="0 0 0.2155"/>
    <axis xyz="0 0 1"/>
    <limit effort="300" lower="-2.09439510239" upper="2.09439510239" velocity="1.308996939"/>
    <dynamics damping="20"/>
  </joint>
  <link name="iiwa_link_4">
    <inertial>
      <origin rpy="0 0 0" xyz="0 0.067 0.034"/>
      <mass value="2.7"/>
      <inertia ixx="0.03" ixy="0" ixz="0" iyy="0.01" iyz="0" izz="0.029"/>
    </inertial>
    <visual>
      <origin rpy="0 0 0" xyz="0 0 0"/>
      <geometry>
        <mesh filename="/home/yanxi/curobo/src/curobo/content/assets/robot/iiwa_allegro_description/meshes/kuka/visual/link_4.dae"/>
      </geometry>
      <material name="Grey"/>
    </visual>
    <collision>
      <origin rpy="0 0 0" xyz="0 0 0"/>
      <geometry>
        <mesh filename="/home/yanxi/curobo/src/curobo/content/assets/robot/iiwa_allegro_description/meshes/kuka/collision/link_4.stl"/>
      </geometry>
      <material name="Grey"/>
    </collision>
  </link>
  <joint name="iiwa_joint_5" type="revolute">
    <parent link="iiwa_link_4"/>
    <child link="iiwa_link_5"/>
    <origin rpy="-1.57079632679 3.14159265359 0" xyz="0 0.1845 0"/>
    <axis xyz="0 0 1"/>
    <limit effort="300" lower="-2.96705972839" upper="2.96705972839" velocity="2.26892802759"/>
    <dynamics damping="20"/>
  </joint>
  <link name="iiwa_link_5">
    <inertial>
      <origin rpy="0 0 0" xyz="0.0001 0.021 0.076"/>
      <mass value="1.7"/>
      <inertia ixx="0.02" ixy="0" ixz="0" iyy="0.018" iyz="0" izz="0.005"/>
    </inertial>
    <visual>
      <origin rpy="0 0 0" xyz="0 0 0"/>
      <geometry>
        <mesh filename="/home/yanxi/curobo/src/curobo/content/assets/robot/iiwa_allegro_description/meshes/kuka/visual/link_5.dae"/>
      </geometry>
      <material name="Grey"/>
    </visual>
    <collision>
      <origin rpy="0 0 0" xyz="0 0 0"/>
      <geometry>
        <mesh filename="/home/yanxi/curobo/src/curobo/content/assets/robot/iiwa_allegro_description/meshes/kuka/collision/link_5.stl"/>
      </geometry>
      <material name="Grey"/>
    </collision>
  </link>
  <joint name="iiwa_joint_6" type="revolute">
    <parent link="iiwa_link_5"/>
    <child link="iiwa_link_6"/>
    <origin rpy="1.57079632679 0 0" xyz="0 0 0.2155"/>
    <axis xyz="0 0 1"/>
    <limit effort="300" lower="-2.09439510239" upper="2.09439510239" velocity="2.35619449019"/>
    <dynamics damping="20"/>
  </joint>
  <link name="iiwa_link_6">
    <inertial>
      <origin rpy="0 0 0" xyz="0 0.0006 0.0004"/>
      <mass value="1.8"/>
      <inertia ixx="0.005" ixy="0" ixz="0" iyy="0.0036" iyz="0" izz="0.0047"/>
    </inertial>
    <visual>
      <origin rpy="0 0 0" xyz="0 0 0"/>
      <geometry>
        <mesh filename="/home/yanxi/curobo/src/curobo/content/assets/robot/iiwa_allegro_description/meshes/kuka/visual/link_6.dae"/>
      </geometry>
      <material name="Grey"/>
    </visual>
    <collision>
      <origin rpy="0 0 0" xyz="0 0 0"/>
      <geometry>
        <mesh filename="/home/yanxi/curobo/src/curobo/content/assets/robot/iiwa_allegro_description/meshes/kuka/collision/link_6.stl"/>
      </geometry>
      <material name="Grey"/>
    </collision>
  </link>
  <joint name="iiwa_joint_7" type="revolute">
    <parent link="iiwa_link_6"/>
    <child link="iiwa_link_7"/>
    <origin rpy="-1.57079632679 3.14159265359 0" xyz="0 0.081 0"/>
    <axis xyz="0 0 1"/>
    <limit effort="300" lower="-3.05432619099" upper="3.05432619099" velocity="2.35619449019"/>
    <dynamics damping="20"/>
  </joint>
  <link name="iiwa_link_7">
    <inertial>
      <origin rpy="0 0 0" xyz="0 0 0.02"/>
      <mass value="0.3"/>
      <inertia ixx="0.001" ixy="0" ixz="0" iyy="0.001" iyz="0" izz="0.001"/>
    </inertial>
    <visual>
      <origin rpy="0 0 0" xyz="0 0 0"/>
      <geometry>
        <mesh filename="/home/yanxi/curobo/src/curobo/content/assets/robot/iiwa_allegro_description/meshes/kuka/visual/link_7.dae"/>
      </geometry>
      <material name="Grey"/>
    </visual>
    <collision>
      <origin rpy="0 0 0" xyz="0 0 0"/>
      <geometry>
        <mesh filename="/home/yanxi/curobo/src/curobo/content/assets/robot/iiwa_allegro_description/meshes/kuka/collision/link_7.stl"/>
      </geometry>
      <material name="Grey"/>
    </collision>
  </link>
  <joint name="iiwa_joint_ee" type="fixed">
    <parent link="iiwa_link_7"/>
    <child link="iiwa_link_ee"/>
    <origin rpy="0 0 0" xyz="0 0 0.045"/>
  </joint>
  <link name="iiwa_link_ee">
  </link>
<!-- </robot> -->

  <!-- This file defines macros for constructing the ReFlex1 Takktile hand model. The primary
       macro is 'reflex1' and all other macros are helper macros used by that one. -->
  <!-- END reflex1 macro -->
  <!-- ======================================================================================= -->
  <!--   LINK MACROS                                                                           -->
  <!-- ======================================================================================= -->
  <!-- ======================================================================================= -->
  <!--   TACTILE MACROS                                                                        -->
  <!-- ======================================================================================= -->
  <!-- ======================================================================================= -->
  <!--   JOINT MACROS                                                                          -->
  <!-- ======================================================================================= -->
  <!-- ======================================================================================= -->
  <!--   GAZEBO MACROS                                                                         -->
  <!-- ======================================================================================= -->
  <!-- KINEMATIC CHAIN specifies the actual links and joints in the robot using the
         helper macros defined below in this file -->
  <link name="reflex_shell_link">
    <visual>
      <origin rpy="0 0 0" xyz="0 0 0"/>
      <geometry>
        <mesh filename="/home/yanxi/curobo/src/curobo/content/assets/robot/iiwa_allegro_description/meshes/reflex/base_link.stl"/>
      </geometry>
      <material name="black"/>
    </visual>
    <inertial>
      <origin rpy="0 0 0" xyz="0 0 0"/>
      <mass value="0.74"/>
      <inertia ixx="0.00165124833333" ixy="0.0" ixz="0.0" iyy="0.00140920666667" iyz="0.0" izz="0.000779281666667"/>
    </inertial>
    <collision>
      <origin rpy="0 0 0" xyz="0 0 0"/>
      <geometry>
        <mesh filename="/home/yanxi/curobo/src/curobo/content/assets/robot/iiwa_allegro_description/meshes/reflex/base_link_coll.stl"/>
      </geometry>
    </collision>
  </link>
  <joint name="reflex_shell_to_pad_joint" type="fixed">
    <origin rpy="1.5707963268 0 -1.5707963268" xyz="0.02 0 0.063"/>
    <parent link="reflex_shell_link"/>
    <child link="reflex_pad_link"/>
    <axis xyz="0 0 0"/>
  </joint>
  <link name="reflex_pad_link">
    <visual>
      <origin rpy="0 0 0" xyz="0 0 0"/>
      <geometry>
        <mesh filename="/home/yanxi/curobo/src/curobo/content/assets/robot/iiwa_allegro_description/meshes/reflex/pad.stl"/>
      </geometry>
      <material name="dark_grey">
        <color rgba="0.2 0.2 0.2 1"/>
      </material>
    </visual>
    <inertial>
      <origin rpy="0 0 0" xyz="0 0 0"/>
      <mass value="0.1"/>
      <inertia ixx="0.000223141666667" ixy="0.0" ixz="0.0" iyy="0.000190433333333" iyz="0.0" izz="0.000105308333333"/>
    </inertial>
    <collision>
      <origin rpy="0 0 0" xyz="0 0 0"/>
      <geometry>
        <mesh filename="/home/yanxi/curobo/src/curobo/content/assets/robot/iiwa_allegro_description/meshes/reflex/pad_coll.stl"/>
      </geometry>
    </collision>
  </link>
  <joint name="reflex_palm_joint" type="fixed">
    <origin rpy="3.14159265359 0 1.5707963268" xyz="0 0 0"/>
    <parent link="reflex_pad_link"/>
    <child link="reflex_palm_link"/>
    <axis xyz="0 0 0"/>
  </joint>
  <link name="reflex_palm_link"/>
  <!-- A dummy link to define the end-effector frame -->
  <joint name="reflex_preshape_joint_1" type="revolute">
    <parent link="reflex_shell_link"/>
    <child link="reflex_swivel_link_1"/>
    <limit effort="15" lower="0.0" upper="1.5707963268" velocity="7"/>
    <dynamics damping="5"/>
    <origin rpy="0 0 0" xyz="0.0503973683071414 -0.026 0.063"/>
    <axis xyz="0 0 -1"/>
  </joint>
  <link name="reflex_swivel_link_1">
    <visual>
      <origin rpy="0 0 0" xyz="0 0 0"/>
      <geometry>
        <mesh filename="/home/yanxi/curobo/src/curobo/content/assets/robot/iiwa_allegro_description/meshes/reflex/swivel_1.stl"/>
      </geometry>
      <material name="black"/>
    </visual>
    <inertial>
      <origin rpy="0 0 0" xyz="0 0 0"/>
      <mass value="0.01"/>
      <inertia ixx="1.60333333333e-06" ixy="0.0" ixz="0.0" iyy="1.15333333333e-06" iyz="0.0" izz="1.25666666667e-06"/>
    </inertial>
    <collision>
      <origin rpy="0 0 0" xyz="0 0 0"/>
      <geometry>
        <mesh filename="/home/yanxi/curobo/src/curobo/content/assets/robot/iiwa_allegro_description/meshes/reflex/swivel_1_coll.stl"/>
      </geometry>
    </collision>
  </link>
  <joint name="reflex_proximal_joint_1" type="revolute">
    <child link="reflex_proximal_link_1"/>
    <axis xyz="0 -1 0"/>
    <limit effort="15" lower="0.0" upper="3.14159265359" velocity="7"/>
    <dynamics damping="5"/>
    <origin rpy="0 0.28 0" xyz="0.01 0 0.0186"/>
    <parent link="reflex_swivel_link_1"/>
  </joint>
  <link name="reflex_proximal_link_1">
    <visual>
      <origin rpy="3.14159265359 0 0" xyz="-0.011 0.007 0.011"/>
      <geometry>
        <mesh filename="/home/yanxi/curobo/src/curobo/content/assets/robot/iiwa_allegro_description/meshes/reflex/proximal.stl"/>
      </geometry>
      <material name="black"/>
    </visual>
    <inertial>
      <origin rpy="3.14159265359 0 0" xyz="-0.011 0.007 0.011"/>
      <mass value="0.01"/>
      <inertia ixx="2.29508333333e-05" ixy="0.0" ixz="0.0" iyy="4.53416666667e-06" iyz="0.0" izz="1.90833333333e-05"/>
    </inertial>
    <collision>
      <origin rpy="3.14159265359 0 0" xyz="-0.011 0.007 0.011"/>
      <geometry>
        <mesh filename="/home/yanxi/curobo/src/curobo/content/assets/robot/iiwa_allegro_description/meshes/reflex/proximal_coll.stl"/>
      </geometry>
    </collision>
  </link>
  <joint name="reflex_proximal_1_to_pad" type="fixed">
    <origin rpy="1.5707963268 0 -1.5707963268" xyz="0 0 0"/>
    <parent link="reflex_proximal_link_1"/>
    <child link="reflex_proximal_pad_link_1"/>
  </joint>
  <link name="reflex_proximal_pad_link_1">
    <visual>
      <origin rpy="1.5707963268 1.5707963268 0" xyz="-0.008 0.014 -0.002"/>
      <geometry>
        <mesh filename="/home/yanxi/curobo/src/curobo/content/assets/robot/iiwa_allegro_description/meshes/reflex/proximal_pad.stl"/>
      </geometry>
      <material name="dark_grey">
        <color rgba="0.2 0.2 0.2 1"/>
      </material>
    </visual>
    <inertial>
      <origin rpy="1.5707963268 1.5707963268 0" xyz="-0.008 0.014 -0.002"/>
      <mass value="0.01"/>
      <inertia ixx="2.29508333333e-05" ixy="0.0" ixz="0.0" iyy="4.22166666667e-06" iyz="0.0" izz="1.87708333333e-05"/>
    </inertial>
    <collision>
      <origin rpy="1.5707963268 1.5707963268 0" xyz="-0.008 0.014 -0.002"/>
      <geometry>
        <mesh filename="/home/yanxi/curobo/src/curobo/content/assets/robot/iiwa_allegro_description/meshes/reflex/proximal_pad_coll.stl"/>
      </geometry>
    </collision>
  </link>
  <joint name="reflex_proximal_1_to_flex" type="fixed">
    <origin rpy="0 0 0" xyz="0.07 0 0.004"/>
    <parent link="reflex_proximal_link_1"/>
    <child link="reflex_flex_link_1"/>
  </joint>
  <link name="reflex_flex_link_1">
    <visual>
      <origin rpy="0 0 0" xyz="0.0005 0 -0.003"/>
      <geometry>
        <box size="0.017 0.014 0.0065"/>
      </geometry>
      <material name="gold">
        <color rgba="0.996078431373 0.847058823529 0.364705882353 1"/>
      </material>
    </visual>
    <inertial>
      <origin rpy="0 0 0" xyz="0 0 0"/>
      <mass value="0.01"/>
      <inertia ixx="3.50833333333e-07" ixy="0.0" ixz="0.0" iyy="2.08333333333e-07" iyz="0.0" izz="1.84166666667e-07"/>
    </inertial>
    <collision>
      <origin rpy="0 0 0" xyz="0 0 0"/>
      <geometry>
        <box size="0.01 0.01 0.01"/>
      </geometry>
    </collision>
  </link>
  <joint name="reflex_flex_to_distal_1" type="fixed">
    <origin rpy="0 0 0" xyz="0 0 0"/>
    <parent link="reflex_flex_link_1"/>
    <child link="reflex_distal_link_1"/>
  </joint>
  <link name="reflex_distal_link_1">
    <visual>
      <origin rpy="3.14159265359 0 0" xyz="-0.077 0.007 0.007"/>
      <geometry>
        <mesh filename="/home/yanxi/curobo/src/curobo/content/assets/robot/iiwa_allegro_description/meshes/reflex/distal.stl"/>
      </geometry>
      <material name="black"/>
    </visual>
    <inertial>
      <origin rpy="3.1459 0 0" xyz="-0.077 0.007 0.007"/>
      <mass value="0.01"/>
      <inertia ixx="2.00175e-05" ixy="0.0" ixz="0.0" iyy="1.50833333333e-06" iyz="0.0" izz="1.89908333333e-05"/>
    </inertial>
    <collision>
      <origin rpy="3.14159265359 0 0" xyz="-0.077 0.007 0.007"/>
      <geometry>
        <mesh filename="/home/yanxi/curobo/src/curobo/content/assets/robot/iiwa_allegro_description/meshes/reflex/distal_coll.stl"/>
      </geometry>
    </collision>
  </link>
  <joint name="reflex_distal_1_to_pad" type="fixed">
    <origin rpy="1.5707963268 0 -1.5707963268" xyz="-0.01 0 0.001"/>
    <parent link="reflex_distal_link_1"/>
    <child link="reflex_distal_pad_link_1"/>
  </joint>
  <link name="reflex_distal_pad_link_1">
    <visual>
      <origin rpy="1.5707963268 1.5707963268 0" xyz="-0.00825 0.009 0.057"/>
      <geometry>
        <mesh filename="/home/yanxi/curobo/src/curobo/content/assets/robot/iiwa_allegro_description/meshes/reflex/distal_pad.stl"/>
      </geometry>
      <material name="dark_grey">
        <color rgba="0.2 0.2 0.2 1"/>
      </material>
    </visual>
    <inertial>
      <origin rpy="1.5707963268 1.5707963268 0" xyz="-0.00825 0.009 0.057"/>
      <mass value="0.01"/>
      <inertia ixx="2.00175e-05" ixy="0.0" ixz="0.0" iyy="1.28833333333e-06" iyz="0.0" izz="1.87708333333e-05"/>
    </inertial>
    <collision>
      <origin rpy="1.5707963268 1.5707963268 0" xyz="-0.00825 0.009 0.057"/>
      <geometry>
        <mesh filename="/home/yanxi/curobo/src/curobo/content/assets/robot/iiwa_allegro_description/meshes/reflex/distal_pad_coll.stl"/>
      </geometry>
    </collision>
  </link>
  <joint name="reflex_preshape_joint_2" type="revolute">
    <parent link="reflex_shell_link"/>
    <child link="reflex_swivel_link_2"/>
    <limit effort="15" lower="0.0" upper="1.5707963268" velocity="7"/>
    <dynamics damping="5"/>
    <origin rpy="0 0 0" xyz="0.0503973683071413 0.026 0.063"/>
    <axis xyz="0 0 1"/>
  </joint>
  <link name="reflex_swivel_link_2">
    <visual>
      <origin rpy="0 0 0" xyz="0 0 0"/>
      <geometry>
        <mesh filename="/home/yanxi/curobo/src/curobo/content/assets/robot/iiwa_allegro_description/meshes/reflex/swivel_2.stl"/>
      </geometry>
      <material name="black"/>
    </visual>
    <inertial>
      <origin rpy="0 0 0" xyz="0 0 0"/>
      <mass value="0.01"/>
      <inertia ixx="1.60333333333e-06" ixy="0.0" ixz="0.0" iyy="1.15333333333e-06" iyz="0.0" izz="1.25666666667e-06"/>
    </inertial>
    <collision>
      <origin rpy="0 0 0" xyz="0 0 0"/>
      <geometry>
        <mesh filename="/home/yanxi/curobo/src/curobo/content/assets/robot/iiwa_allegro_description/meshes/reflex/swivel_2_coll.stl"/>
      </geometry>
    </collision>
  </link>
  <joint name="reflex_proximal_joint_2" type="revolute">
    <child link="reflex_proximal_link_2"/>
    <axis xyz="0 -1 0"/>
    <limit effort="15" lower="0.0" upper="3.14159265359" velocity="7"/>
    <dynamics damping="5"/>
    <origin rpy="0 0.28 0" xyz="0.01 0 0.0186"/>
    <parent link="reflex_swivel_link_2"/>
  </joint>
  <link name="reflex_proximal_link_2">
    <visual>
      <origin rpy="3.14159265359 0 0" xyz="-0.011 0.007 0.011"/>
      <geometry>
        <mesh filename="/home/yanxi/curobo/src/curobo/content/assets/robot/iiwa_allegro_description/meshes/reflex/proximal.stl"/>
      </geometry>
      <material name="black"/>
    </visual>
    <inertial>
      <origin rpy="3.14159265359 0 0" xyz="-0.011 0.007 0.011"/>
      <mass value="0.01"/>
      <inertia ixx="2.29508333333e-05" ixy="0.0" ixz="0.0" iyy="4.53416666667e-06" iyz="0.0" izz="1.90833333333e-05"/>
    </inertial>
    <collision>
      <origin rpy="3.14159265359 0 0" xyz="-0.011 0.007 0.011"/>
      <geometry>
        <mesh filename="/home/yanxi/curobo/src/curobo/content/assets/robot/iiwa_allegro_description/meshes/reflex/proximal_coll.stl"/>
      </geometry>
    </collision>
  </link>
  <joint name="reflex_proximal_2_to_pad" type="fixed">
    <origin rpy="1.5707963268 0 -1.5707963268" xyz="0 0 0"/>
    <parent link="reflex_proximal_link_2"/>
    <child link="reflex_proximal_pad_link_2"/>
  </joint>
  <link name="reflex_proximal_pad_link_2">
    <visual>
      <origin rpy="1.5707963268 1.5707963268 0" xyz="-0.008 0.014 -0.002"/>
      <geometry>
        <mesh filename="/home/yanxi/curobo/src/curobo/content/assets/robot/iiwa_allegro_description/meshes/reflex/proximal_pad.stl"/>
      </geometry>
      <material name="dark_grey">
        <color rgba="0.2 0.2 0.2 1"/>
      </material>
    </visual>
    <inertial>
      <origin rpy="1.5707963268 1.5707963268 0" xyz="-0.008 0.014 -0.002"/>
      <mass value="0.01"/>
      <inertia ixx="2.29508333333e-05" ixy="0.0" ixz="0.0" iyy="4.22166666667e-06" iyz="0.0" izz="1.87708333333e-05"/>
    </inertial>
    <collision>
      <origin rpy="1.5707963268 1.5707963268 0" xyz="-0.008 0.014 -0.002"/>
      <geometry>
        <mesh filename="/home/yanxi/curobo/src/curobo/content/assets/robot/iiwa_allegro_description/meshes/reflex/proximal_pad_coll.stl"/>
      </geometry>
    </collision>
  </link>
  <joint name="reflex_proximal_2_to_flex" type="fixed">
    <origin rpy="0 0 0" xyz="0.07 0 0.004"/>
    <parent link="reflex_proximal_link_2"/>
    <child link="reflex_flex_link_2"/>
  </joint>
  <link name="reflex_flex_link_2">
    <visual>
      <origin rpy="0 0 0" xyz="0.0005 0 -0.003"/>
      <geometry>
        <box size="0.017 0.014 0.0065"/>
      </geometry>
      <material name="gold">
        <color rgba="0.996078431373 0.847058823529 0.364705882353 1"/>
      </material>
    </visual>
    <inertial>
      <origin rpy="0 0 0" xyz="0 0 0"/>
      <mass value="0.01"/>
      <inertia ixx="3.50833333333e-07" ixy="0.0" ixz="0.0" iyy="2.08333333333e-07" iyz="0.0" izz="1.84166666667e-07"/>
    </inertial>
    <collision>
      <origin rpy="0 0 0" xyz="0 0 0"/>
      <geometry>
        <box size="0.01 0.01 0.01"/>
      </geometry>
    </collision>
  </link>
  <joint name="reflex_flex_to_distal_2" type="fixed">
    <origin rpy="0 0 0" xyz="0 0 0"/>
    <parent link="reflex_flex_link_2"/>
    <child link="reflex_distal_link_2"/>
  </joint>
  <link name="reflex_distal_link_2">
    <visual>
      <origin rpy="3.14159265359 0 0" xyz="-0.077 0.007 0.007"/>
      <geometry>
        <mesh filename="/home/yanxi/curobo/src/curobo/content/assets/robot/iiwa_allegro_description/meshes/reflex/distal.stl"/>
      </geometry>
      <material name="black"/>
    </visual>
    <inertial>
      <origin rpy="3.1459 0 0" xyz="-0.077 0.007 0.007"/>
      <mass value="0.01"/>
      <inertia ixx="2.00175e-05" ixy="0.0" ixz="0.0" iyy="1.50833333333e-06" iyz="0.0" izz="1.89908333333e-05"/>
    </inertial>
    <collision>
      <origin rpy="3.14159265359 0 0" xyz="-0.077 0.007 0.007"/>
      <geometry>
        <mesh filename="/home/yanxi/curobo/src/curobo/content/assets/robot/iiwa_allegro_description/meshes/reflex/distal_coll.stl"/>
      </geometry>
    </collision>
  </link>
  <joint name="reflex_distal_2_to_pad" type="fixed">
    <origin rpy="1.5707963268 0 -1.5707963268" xyz="-0.01 0 0.001"/>
    <parent link="reflex_distal_link_2"/>
    <child link="reflex_distal_pad_link_2"/>
  </joint>
  <link name="reflex_distal_pad_link_2">
    <visual>
      <origin rpy="1.5707963268 1.5707963268 0" xyz="-0.00825 0.009 0.057"/>
      <geometry>
        <mesh filename="/home/yanxi/curobo/src/curobo/content/assets/robot/iiwa_allegro_description/meshes/reflex/distal_pad.stl"/>
      </geometry>
      <material name="dark_grey">
        <color rgba="0.2 0.2 0.2 1"/>
      </material>
    </visual>
    <inertial>
      <origin rpy="1.5707963268 1.5707963268 0" xyz="-0.00825 0.009 0.057"/>
      <mass value="0.01"/>
      <inertia ixx="2.00175e-05" ixy="0.0" ixz="0.0" iyy="1.28833333333e-06" iyz="0.0" izz="1.87708333333e-05"/>
    </inertial>
    <collision>
      <origin rpy="1.5707963268 1.5707963268 0" xyz="-0.00825 0.009 0.057"/>
      <geometry>
        <mesh filename="/home/yanxi/curobo/src/curobo/content/assets/robot/iiwa_allegro_description/meshes/reflex/distal_pad_coll.stl"/>
      </geometry>
    </collision>
  </link>
  <joint name="reflex_proximal_joint_3" type="revolute">
    <child link="reflex_proximal_link_3"/>
    <axis xyz="0 -1 0"/>
    <limit effort="15" lower="0.0" upper="3.14159265359" velocity="7"/>
    <dynamics damping="5"/>
    <origin rpy="0 0.28 3.14159265359" xyz="-0.03 0 0.0816"/>
    <parent link="reflex_shell_link"/>
  </joint>
  <link name="reflex_proximal_link_3">
    <visual>
      <origin rpy="3.14159265359 0 0" xyz="-0.011 0.007 0.011"/>
      <geometry>
        <mesh filename="/home/yanxi/curobo/src/curobo/content/assets/robot/iiwa_allegro_description/meshes/reflex/proximal.stl"/>
      </geometry>
      <material name="black"/>
    </visual>
    <inertial>
      <origin rpy="3.14159265359 0 0" xyz="-0.011 0.007 0.011"/>
      <mass value="0.01"/>
      <inertia ixx="2.29508333333e-05" ixy="0.0" ixz="0.0" iyy="4.53416666667e-06" iyz="0.0" izz="1.90833333333e-05"/>
    </inertial>
    <collision>
      <origin rpy="3.14159265359 0 0" xyz="-0.011 0.007 0.011"/>
      <geometry>
        <mesh filename="/home/yanxi/curobo/src/curobo/content/assets/robot/iiwa_allegro_description/meshes/reflex/proximal_coll.stl"/>
      </geometry>
    </collision>
  </link>
  <joint name="reflex_proximal_3_to_pad" type="fixed">
    <origin rpy="1.5707963268 0 -1.5707963268" xyz="0 0 0"/>
    <parent link="reflex_proximal_link_3"/>
    <child link="reflex_proximal_pad_link_3"/>
  </joint>
  <link name="reflex_proximal_pad_link_3">
    <visual>
      <origin rpy="1.5707963268 1.5707963268 0" xyz="-0.008 0.014 -0.002"/>
      <geometry>
        <mesh filename="/home/yanxi/curobo/src/curobo/content/assets/robot/iiwa_allegro_description/meshes/reflex/proximal_pad.stl"/>
      </geometry>
      <material name="dark_grey">
        <color rgba="0.2 0.2 0.2 1"/>
      </material>
    </visual>
    <inertial>
      <origin rpy="1.5707963268 1.5707963268 0" xyz="-0.008 0.014 -0.002"/>
      <mass value="0.01"/>
      <inertia ixx="2.29508333333e-05" ixy="0.0" ixz="0.0" iyy="4.22166666667e-06" iyz="0.0" izz="1.87708333333e-05"/>
    </inertial>
    <collision>
      <origin rpy="1.5707963268 1.5707963268 0" xyz="-0.008 0.014 -0.002"/>
      <geometry>
        <mesh filename="/home/yanxi/curobo/src/curobo/content/assets/robot/iiwa_allegro_description/meshes/reflex/proximal_pad_coll.stl"/>
      </geometry>
    </collision>
  </link>
  <joint name="reflex_proximal_3_to_flex" type="fixed">
    <origin rpy="0 0 0" xyz="0.07 0 0.004"/>
    <parent link="reflex_proximal_link_3"/>
    <child link="reflex_flex_link_3"/>
  </joint>
  <link name="reflex_flex_link_3">
    <visual>
      <origin rpy="0 0 0" xyz="0.0005 0 -0.003"/>
      <geometry>
        <box size="0.017 0.014 0.0065"/>
      </geometry>
      <material name="gold">
        <color rgba="0.996078431373 0.847058823529 0.364705882353 1"/>
      </material>
    </visual>
    <inertial>
      <origin rpy="0 0 0" xyz="0 0 0"/>
      <mass value="0.01"/>
      <inertia ixx="3.50833333333e-07" ixy="0.0" ixz="0.0" iyy="2.08333333333e-07" iyz="0.0" izz="1.84166666667e-07"/>
    </inertial>
    <collision>
      <origin rpy="0 0 0" xyz="0 0 0"/>
      <geometry>
        <box size="0.01 0.01 0.01"/>
      </geometry>
    </collision>
  </link>
  <joint name="reflex_flex_to_distal_3" type="fixed">
    <origin rpy="0 0 0" xyz="0 0 0"/>
    <parent link="reflex_flex_link_3"/>
    <child link="reflex_distal_link_3"/>
  </joint>
  <link name="reflex_distal_link_3">
    <visual>
      <origin rpy="3.14159265359 0 0" xyz="-0.077 0.007 0.007"/>
      <geometry>
        <mesh filename="/home/yanxi/curobo/src/curobo/content/assets/robot/iiwa_allegro_description/meshes/reflex/distal.stl"/>
      </geometry>
      <material name="black"/>
    </visual>
    <inertial>
      <origin rpy="3.1459 0 0" xyz="-0.077 0.007 0.007"/>
      <mass value="0.01"/>
      <inertia ixx="2.00175e-05" ixy="0.0" ixz="0.0" iyy="1.50833333333e-06" iyz="0.0" izz="1.89908333333e-05"/>
    </inertial>
    <collision>
      <origin rpy="3.14159265359 0 0" xyz="-0.077 0.007 0.007"/>
      <geometry>
        <mesh filename="/home/yanxi/curobo/src/curobo/content/assets/robot/iiwa_allegro_description/meshes/reflex/distal_coll.stl"/>
      </geometry>
    </collision>
  </link>
  <joint name="reflex_distal_3_to_pad" type="fixed">
    <origin rpy="1.5707963268 0 -1.5707963268" xyz="-0.01 0 0.001"/>
    <parent link="reflex_distal_link_3"/>
    <child link="reflex_distal_pad_link_3"/>
  </joint>
  <link name="reflex_distal_pad_link_3">
    <visual>
      <origin rpy="1.5707963268 1.5707963268 0" xyz="-0.00825 0.009 0.057"/>
      <geometry>
        <mesh filename="/home/yanxi/curobo/src/curobo/content/assets/robot/iiwa_allegro_description/meshes/reflex/distal_pad.stl"/>
      </geometry>
      <material name="dark_grey">
        <color rgba="0.2 0.2 0.2 1"/>
      </material>
    </visual>
    <inertial>
      <origin rpy="1.5707963268 1.5707963268 0" xyz="-0.00825 0.009 0.057"/>
      <mass value="0.01"/>
      <inertia ixx="2.00175e-05" ixy="0.0" ixz="0.0" iyy="1.28833333333e-06" iyz="0.0" izz="1.87708333333e-05"/>
    </inertial>
    <collision>
      <origin rpy="1.5707963268 1.5707963268 0" xyz="-0.00825 0.009 0.057"/>
      <geometry>
        <mesh filename="/home/yanxi/curobo/src/curobo/content/assets/robot/iiwa_allegro_description/meshes/reflex/distal_pad_coll.stl"/>
      </geometry>
    </collision>
  </link>
  <!-- Mount + screws -->
  <link name="reflex2_to_iiwa_mount">
    <inertial>
      <origin rpy="0 0 0" xyz="0 0 0"/>
      <mass value="0.064"/>
      <inertia ixx="2.0368e-05" ixy="0.0" ixz="0.0" iyy="2.0368e-05" iyz="0.0" izz="3.92e-05"/>
    </inertial>
    <visual>
      <origin rpy="0 0 0" xyz="0 0 0"/>
      <geometry>
        <cylinder length="0.012" radius="0.035"/>
      </geometry>
      <material name="black"/>
    </visual>
    <collision>
      <origin rpy="0 0 0" xyz="0 0 0"/>
      <geometry>
        <cylinder length="0.012" radius="0.035"/>
      </geometry>
    </collision>
  </link>
  <!-- Made up value -->
  <link name="reflex2_extra_shell">
    <inertial>
      <origin rpy="0 0 0" xyz="0 0 0"/>
      <mass value="0.01"/>
      <inertia ixx="4.02083333333e-06" ixy="0.0" ixz="0.0" iyy="4.02083333333e-06" iyz="0.0" izz="8e-06"/>
    </inertial>
    <visual>
      <origin rpy="0 0 0" xyz="0 0 0"/>
      <geometry>
        <cylinder length="0.005" radius="0.04"/>
      </geometry>
      <material name="black"/>
    </visual>
    <collision>
      <origin rpy="0 0 0" xyz="0 0 0"/>
      <geometry>
        <cylinder length="0.005" radius="0.04"/>
      </geometry>
    </collision>
  </link>
  <joint name="iiwa_to_mount" type="fixed">
    <parent link="iiwa_link_ee"/>
    <child link="reflex2_to_iiwa_mount"/>
    <origin rpy="0 0 0" xyz="0 0 0.006"/>
  </joint>
  <joint name="mount_to_extra_shell" type="fixed">
    <parent link="reflex2_to_iiwa_mount"/>
    <child link="reflex2_extra_shell"/>
    <origin rpy="0 0 0" xyz="0 0 0.0085"/>
  </joint>
  <joint name="extra_shell_to_reflex" type="fixed">
    <parent link="reflex2_extra_shell"/>
    <child link="reflex_shell_link"/>
    <origin rpy="0 0 3.14159265359" xyz="0.014 0 0.0025"/>
  </joint>
</robot>

