<?xml version="1.0" encoding="utf-8"?>
<!-- =================================================================================== -->
<!-- |    This document was autogenerated by xacro from robots/iiwa.robot.xacro        | -->
<!-- |    EDITING THIS FILE BY HAND IS NOT RECOMMENDED                                 | -->
<!-- =================================================================================== -->
<robot name="iiwa">
  <!-- ==================================================================================== -->
  <!-- ==================================================================================== -->
  <!-- END effort_transmission macro -->
  <!-- ======================================================================================= -->
  <!--   MATERIALS                                                                             -->
  <!-- ======================================================================================= -->
  <material name="Grey">
    <color rgba="0.7 0.7 0.7 1.0"/>
  </material>
  <link name="world"/>
  <link name="robot_table_link">
    <inertial>
      <origin rpy="0 0 0" xyz="0 0 0"/>
      <mass value="200"/>
      <inertia ixx="0.1" ixy="0" ixz="0" iyy="0.1" iyz="0" izz="0.1"/>
    </inertial>
    <visual>
      <origin rpy="0 0 0" xyz="0 0 0"/>
      <geometry>
        <mesh filename="/home/yanxi/curobo/src/curobo/content/assets/robot/iiwa_allegro_description/meshes/kuka/visual/robot_table_link.dae"/>
      </geometry>
      <material name="table_color">
        <color rgba="0.8235294117647058 0.6666666666666666 0.47058823529411764 1.0"/>
      </material>
    </visual>
    <collision>
      <origin rpy="0 0 0" xyz="0 0 0"/>
      <geometry>
        <mesh filename="/home/yanxi/curobo/src/curobo/content/assets/robot/iiwa_allegro_description/meshes/kuka/collision/robot_table_link.stl"/>
      </geometry>
    </collision>
  </link>
  <gazebo reference="robot_table_link">
    <visual>
      <material>
        <ambient>0.8235294117647058 0.6666666666666666 0.47058823529411764 1.0</ambient>
        <diffuse>0.50754 0.50754 0.50754 1.0</diffuse>
        <specular>1 1 1 0</specular>
        <emissive>0.0 0.0 0.0 0.0</emissive>
      </material>
    </visual>
  </gazebo>
  <joint name="world_to_right_table" type="fixed">
    <!-- Change this origin to adjust relative pose of robot tables -->
    <origin rpy="0 0 0" xyz="0 -0.45625 0.295"/>
    <parent link="world"/>
    <child link="robot_table_link"/>
  </joint>
  <joint name="robot_table_link_to_iiwa" type="fixed">
    <origin rpy="0 0 3.141592653589793" xyz="0 0 0.295"/>
    <parent link="robot_table_link"/>
    <child link="iiwa_link_0"/>
  </joint>
  <link name="iiwa_link_0">
    <inertial>
      <origin rpy="0 0 0" xyz="-0.1 0 0.07"/>
      <mass value="5"/>
      <inertia ixx="0.05" ixy="0" ixz="0" iyy="0.06" iyz="0" izz="0.03"/>
    </inertial>
    <visual>
      <origin rpy="0 0 0" xyz="0 0 0"/>
      <geometry>
        <mesh filename="/home/yanxi/curobo/src/curobo/content/assets/robot/iiwa_allegro_description/meshes/kuka/visual/link_0.dae"/>
      </geometry>
      <material name="Grey"/>
    </visual>
    <collision>
      <origin rpy="0 0 0" xyz="0 0 0"/>
      <geometry>
        <mesh filename="/home/yanxi/curobo/src/curobo/content/assets/robot/iiwa_allegro_description/meshes/kuka/collision/link_0.stl"/>
      </geometry>
      <material name="Grey"/>
    </collision>
  </link>
  <joint name="iiwa_joint_1" type="revolute">
    <parent link="iiwa_link_0"/>
    <child link="iiwa_link_1"/>
    <origin rpy="0 0 0" xyz="0 0 0.1575"/>
    <axis xyz="0 0 1"/>
    <limit effort="300" lower="-2.9670597283903604" upper="2.9670597283903604" velocity="1.4835298641951802"/>
    <dynamics damping="20"/>
  </joint>
  <link name="iiwa_link_1">
    <inertial>
      <origin rpy="0 0 0" xyz="0 -0.03 0.12"/>
      <mass value="4"/>
      <inertia ixx="0.1" ixy="0" ixz="0" iyy="0.09" iyz="0" izz="0.02"/>
    </inertial>
    <visual>
      <origin rpy="0 0 0" xyz="0 0 0"/>
      <geometry>
        <mesh filename="/home/yanxi/curobo/src/curobo/content/assets/robot/iiwa_allegro_description/meshes/kuka/visual/link_1.dae"/>
      </geometry>
      <material name="Grey"/>
    </visual>
    <collision>
      <origin rpy="0 0 0" xyz="0 0 0"/>
      <geometry>
        <mesh filename="/home/yanxi/curobo/src/curobo/content/assets/robot/iiwa_allegro_description/meshes/kuka/collision/link_1.stl"/>
      </geometry>
      <material name="Grey"/>
    </collision>
  </link>
  <joint name="iiwa_joint_2" type="revolute">
    <parent link="iiwa_link_1"/>
    <child link="iiwa_link_2"/>
    <origin rpy="1.5707963267948966   0 3.141592653589793" xyz="0 0 0.2025"/>
    <axis xyz="0 0 1"/>
    <limit effort="300" lower="-2.0943951023931953" upper="2.0943951023931953" velocity="1.4835298641951802"/>
    <dynamics damping="20"/>
  </joint>
  <link name="iiwa_link_2">
    <inertial>
      <origin rpy="0 0 0" xyz="0.0003 0.059 0.042"/>
      <mass value="4"/>
      <inertia ixx="0.05" ixy="0" ixz="0" iyy="0.018" iyz="0" izz="0.044"/>
    </inertial>
    <visual>
      <origin rpy="0 0 0" xyz="0 0 0"/>
      <geometry>
        <mesh filename="/home/yanxi/curobo/src/curobo/content/assets/robot/iiwa_allegro_description/meshes/kuka/visual/link_2.dae"/>
      </geometry>
      <material name="Grey"/>
    </visual>
    <collision>
      <origin rpy="0 0 0" xyz="0 0 0"/>
      <geometry>
        <mesh filename="/home/yanxi/curobo/src/curobo/content/assets/robot/iiwa_allegro_description/meshes/kuka/collision/link_2.stl"/>
      </geometry>
      <material name="Grey"/>
    </collision>
  </link>
  <joint name="iiwa_joint_3" type="revolute">
    <parent link="iiwa_link_2"/>
    <child link="iiwa_link_3"/>
    <origin rpy="1.5707963267948966 0 3.141592653589793" xyz="0 0.2045 0"/>
    <axis xyz="0 0 1"/>
    <limit effort="300" lower="-2.9670597283903604" upper="2.9670597283903604" velocity="1.7453292519943295"/>
    <dynamics damping="20"/>
  </joint>
  <link name="iiwa_link_3">
    <inertial>
      <origin rpy="0 0 0" xyz="0 0.03 0.13"/>
      <mass value="3"/>
      <inertia ixx="0.08" ixy="0" ixz="0" iyy="0.075" iyz="0" izz="0.01"/>
    </inertial>
    <visual>
      <origin rpy="0 0 0" xyz="0 0 0"/>
      <geometry>
        <mesh filename="/home/yanxi/curobo/src/curobo/content/assets/robot/iiwa_allegro_description/meshes/kuka/visual/link_3.dae"/>
      </geometry>
      <material name="Grey"/>
    </visual>
    <collision>
      <origin rpy="0 0 0" xyz="0 0 0"/>
      <geometry>
        <mesh filename="/home/yanxi/curobo/src/curobo/content/assets/robot/iiwa_allegro_description/meshes/kuka/collision/link_3.stl"/>
      </geometry>
      <material name="Grey"/>
    </collision>
  </link>
  <joint name="iiwa_joint_4" type="revolute">
    <parent link="iiwa_link_3"/>
    <child link="iiwa_link_4"/>
    <origin rpy="1.5707963267948966 0 0" xyz="0 0 0.2155"/>
    <axis xyz="0 0 1"/>
    <limit effort="300" lower="-2.0943951023931953" upper="2.0943951023931953" velocity="1.3089969389957472"/>
    <dynamics damping="20"/>
  </joint>
  <link name="iiwa_link_4">
    <inertial>
      <origin rpy="0 0 0" xyz="0 0.067 0.034"/>
      <mass value="2.7"/>
      <inertia ixx="0.03" ixy="0" ixz="0" iyy="0.01" iyz="0" izz="0.029"/>
    </inertial>
    <visual>
      <origin rpy="0 0 0" xyz="0 0 0"/>
      <geometry>
        <mesh filename="/home/yanxi/curobo/src/curobo/content/assets/robot/iiwa_allegro_description/meshes/kuka/visual/link_4.dae"/>
      </geometry>
      <material name="Grey"/>
    </visual>
    <collision>
      <origin rpy="0 0 0" xyz="0 0 0"/>
      <geometry>
        <mesh filename="/home/yanxi/curobo/src/curobo/content/assets/robot/iiwa_allegro_description/meshes/kuka/collision/link_4.stl"/>
      </geometry>
      <material name="Grey"/>
    </collision>
  </link>
  <joint name="iiwa_joint_5" type="revolute">
    <parent link="iiwa_link_4"/>
    <child link="iiwa_link_5"/>
    <origin rpy="-1.5707963267948966 3.141592653589793 0" xyz="0 0.1845 0"/>
    <axis xyz="0 0 1"/>
    <limit effort="300" lower="-2.9670597283903604" upper="2.9670597283903604" velocity="2.2689280275926285"/>
    <dynamics damping="20"/>
  </joint>
  <link name="iiwa_link_5">
    <inertial>
      <origin rpy="0 0 0" xyz="0.0001 0.021 0.076"/>
      <mass value="1.7"/>
      <inertia ixx="0.02" ixy="0" ixz="0" iyy="0.018" iyz="0" izz="0.005"/>
    </inertial>
    <visual>
      <origin rpy="0 0 0" xyz="0 0 0"/>
      <geometry>
        <mesh filename="/home/yanxi/curobo/src/curobo/content/assets/robot/iiwa_allegro_description/meshes/kuka/visual/link_5.dae"/>
      </geometry>
      <material name="Grey"/>
    </visual>
    <collision>
      <origin rpy="0 0 0" xyz="0 0 0"/>
      <geometry>
        <mesh filename="/home/yanxi/curobo/src/curobo/content/assets/robot/iiwa_allegro_description/meshes/kuka/collision/link_5.stl"/>
      </geometry>
      <material name="Grey"/>
    </collision>
  </link>
  <joint name="iiwa_joint_6" type="revolute">
    <parent link="iiwa_link_5"/>
    <child link="iiwa_link_6"/>
    <origin rpy="1.5707963267948966 0 0" xyz="0 0 0.2155"/>
    <axis xyz="0 0 1"/>
    <limit effort="300" lower="-2.0943951023931953" upper="2.0943951023931953" velocity="2.356194490192345"/>
    <dynamics damping="20"/>
  </joint>
  <link name="iiwa_link_6">
    <inertial>
      <origin rpy="0 0 0" xyz="0 0.0006 0.0004"/>
      <mass value="1.8"/>
      <inertia ixx="0.005" ixy="0" ixz="0" iyy="0.0036" iyz="0" izz="0.0047"/>
    </inertial>
    <visual>
      <origin rpy="0 0 0" xyz="0 0 0"/>
      <geometry>
        <mesh filename="/home/yanxi/curobo/src/curobo/content/assets/robot/iiwa_allegro_description/meshes/kuka/visual/link_6.dae"/>
      </geometry>
      <material name="Grey"/>
    </visual>
    <collision>
      <origin rpy="0 0 0" xyz="0 0 0"/>
      <geometry>
        <mesh filename="/home/yanxi/curobo/src/curobo/content/assets/robot/iiwa_allegro_description/meshes/kuka/collision/link_6.stl"/>
      </geometry>
      <material name="Grey"/>
    </collision>
  </link>
  <joint name="iiwa_joint_7" type="revolute">
    <parent link="iiwa_link_6"/>
    <child link="iiwa_link_7"/>
    <origin rpy="-1.5707963267948966 3.141592653589793 0" xyz="0 0.081 0"/>
    <axis xyz="0 0 1"/>
    <limit effort="300" lower="-3.0543261909900763" upper="3.0543261909900763" velocity="2.356194490192345"/>
    <dynamics damping="20"/>
  </joint>
  <link name="iiwa_link_7">
    <inertial>
      <origin rpy="0 0 0" xyz="0 0 0.02"/>
      <mass value="0.3"/>
      <inertia ixx="0.001" ixy="0" ixz="0" iyy="0.001" iyz="0" izz="0.001"/>
    </inertial>
    <visual>
      <origin rpy="0 0 0" xyz="0 0 0"/>
      <geometry>
        <mesh filename="/home/yanxi/curobo/src/curobo/content/assets/robot/iiwa_allegro_description/meshes/kuka/visual/link_7.dae"/>
      </geometry>
      <material name="Grey"/>
    </visual>
    <collision>
      <origin rpy="0 0 0" xyz="0 0 0"/>
      <geometry>
        <mesh filename="/home/yanxi/curobo/src/curobo/content/assets/robot/iiwa_allegro_description/meshes/kuka/collision/link_7.stl"/>
      </geometry>
      <material name="Grey"/>
    </collision>
  </link>
  <!-- <joint name="iiwa_joint_ee" type="fixed">
    <parent link="iiwa_link_7"/>
    <child link="iiwa_link_ee"/>
    <origin rpy="0 0 0" xyz="0 0 0.045"/>
  </joint>
  <link name="iiwa_link_ee">
    </link> -->
  <transmission name="iiwa_trans_1">
    <type>transmission_interface/SimpleTransmission</type>
    <joint name="iiwa_joint_1">
      <hardwareInterface>hardware_interface/EffortJointInterface</hardwareInterface>
    </joint>
    <actuator name="iiwa_motor_1">
      <hardwareInterface>hardware_interface/EffortJointInterface</hardwareInterface>
      <mechanicalReduction>1</mechanicalReduction>
    </actuator>
  </transmission>
  <transmission name="iiwa_trans_2">
    <type>transmission_interface/SimpleTransmission</type>
    <joint name="iiwa_joint_2">
      <hardwareInterface>hardware_interface/EffortJointInterface</hardwareInterface>
    </joint>
    <actuator name="iiwa_motor_2">
      <hardwareInterface>hardware_interface/EffortJointInterface</hardwareInterface>
      <mechanicalReduction>1</mechanicalReduction>
    </actuator>
  </transmission>
  <transmission name="iiwa_trans_3">
    <type>transmission_interface/SimpleTransmission</type>
    <joint name="iiwa_joint_3">
      <hardwareInterface>hardware_interface/EffortJointInterface</hardwareInterface>
    </joint>
    <actuator name="iiwa_motor_3">
      <hardwareInterface>hardware_interface/EffortJointInterface</hardwareInterface>
      <mechanicalReduction>1</mechanicalReduction>
    </actuator>
  </transmission>
  <transmission name="iiwa_trans_4">
    <type>transmission_interface/SimpleTransmission</type>
    <joint name="iiwa_joint_4">
      <hardwareInterface>hardware_interface/EffortJointInterface</hardwareInterface>
    </joint>
    <actuator name="iiwa_motor_4">
      <hardwareInterface>hardware_interface/EffortJointInterface</hardwareInterface>
      <mechanicalReduction>1</mechanicalReduction>
    </actuator>
  </transmission>
  <transmission name="iiwa_trans_5">
    <type>transmission_interface/SimpleTransmission</type>
    <joint name="iiwa_joint_5">
      <hardwareInterface>hardware_interface/EffortJointInterface</hardwareInterface>
    </joint>
    <actuator name="iiwa_motor_5">
      <hardwareInterface>hardware_interface/EffortJointInterface</hardwareInterface>
      <mechanicalReduction>1</mechanicalReduction>
    </actuator>
  </transmission>
  <transmission name="iiwa_trans_6">
    <type>transmission_interface/SimpleTransmission</type>
    <joint name="iiwa_joint_6">
      <hardwareInterface>hardware_interface/EffortJointInterface</hardwareInterface>
    </joint>
    <actuator name="iiwa_motor_6">
      <hardwareInterface>hardware_interface/EffortJointInterface</hardwareInterface>
      <mechanicalReduction>1</mechanicalReduction>
    </actuator>
  </transmission>
  <transmission name="iiwa_trans_7">
    <type>transmission_interface/SimpleTransmission</type>
    <joint name="iiwa_joint_7">
      <hardwareInterface>hardware_interface/EffortJointInterface</hardwareInterface>
    </joint>
    <actuator name="iiwa_motor_7">
      <hardwareInterface>hardware_interface/EffortJointInterface</hardwareInterface>
      <mechanicalReduction>1</mechanicalReduction>
    </actuator>
  </transmission>
  <!-- TODO these selfCollide tags are necessary for the arms to be able to collide with
           each other, which definitely seems necessary for bimanual as you want to render
           when one arm collides with other. However, there has been some problem with controlling
           any hands attached to robots when these tags are enabled. I haven't yet tried also
           adding the tags to the hands, which should be done anyways, so give that a shot
           and see if hand can be controlled then with all selfCollide tags active on whole model. -->
  <gazebo reference="iiwa_link_0">
    <material>Gazebo/Grey</material>
    <mu1>0.2</mu1>
    <mu2>0.2</mu2>
    <!-- <selfCollide>true</selfCollide> -->
  </gazebo>
  <gazebo reference="iiwa_link_1">
    <material>Gazebo/Grey</material>
    <mu1>0.2</mu1>
    <mu2>0.2</mu2>
    <!-- <selfCollide>true</selfCollide> -->
  </gazebo>
  <gazebo reference="iiwa_link_2">
    <material>Gazebo/Grey</material>
    <mu1>0.2</mu1>
    <mu2>0.2</mu2>
    <!-- <selfCollide>true</selfCollide> -->
  </gazebo>
  <gazebo reference="iiwa_link_3">
    <material>Gazebo/Grey</material>
    <mu1>0.2</mu1>
    <mu2>0.2</mu2>
    <!-- <selfCollide>true</selfCollide> -->
  </gazebo>
  <gazebo reference="iiwa_link_4">
    <material>Gazebo/Grey</material>
    <mu1>0.2</mu1>
    <mu2>0.2</mu2>
    <!-- <selfCollide>true</selfCollide> -->
  </gazebo>
  <gazebo reference="iiwa_link_5">
    <material>Gazebo/Grey</material>
    <mu1>0.2</mu1>
    <mu2>0.2</mu2>
    <!-- <selfCollide>true</selfCollide> -->
  </gazebo>
  <gazebo reference="iiwa_link_6">
    <material>Gazebo/Grey</material>
    <mu1>0.2</mu1>
    <mu2>0.2</mu2>
    <!-- <selfCollide>true</selfCollide> -->
  </gazebo>
  <gazebo reference="iiwa_link_7">
    <material>Gazebo/Grey</material>
    <mu1>0.2</mu1>
    <mu2>0.2</mu2>
    <!-- <selfCollide>true</selfCollide> -->
  </gazebo>
  <link name="robotiq_base_link">
    <inertial>
      <origin rpy="0 0 0" xyz="8.625E-08 -4.6583E-06 0.03145"/>
      <mass value="0.22652"/>
      <inertia ixx="0.00020005" ixy="-4.2442E-10" ixz="-2.9069E-10" iyy="0.00017832" iyz="-3.4402E-08" izz="0.00013478"/>
    </inertial>
    <visual>
      <origin rpy="0 0 0" xyz="0 0 0"/>
      <geometry>
        <mesh filename="/home/yanxi/curobo/src/curobo/content/assets/robot/iiwa_allegro_description/meshes/robotiq/visual/robotiq_arg2f_base_link.stl"/>
      </geometry>
      <material name="">
        <color rgba="0.1 0.1 0.1 1"/>
      </material>
    </visual>
    <collision>
      <origin rpy="0 0 0" xyz="0 0 0"/>
      <geometry>
        <mesh filename="/home/yanxi/curobo/src/curobo/content/assets/robot/iiwa_allegro_description/meshes/robotiq/collision/robotiq_arg2f_base_link.stl"/>
      </geometry>
    </collision>
  </link>
  <joint name="robotiq_palm_joint" type="fixed">
    <origin rpy="0 -1.570796326795 -1.570796326795" xyz="0 0 0"/>
    <parent link="robotiq_base_link"/>
    <child link="robotiq_palm_link"/>
    <axis xyz="0 0 0"/>
  </joint>
  <link name="robotiq_palm_link"/>
  <!-- A dummy link to define the end-effector frame -->
  <link name="robotiq_left_outer_knuckle">
    <inertial>
      <origin rpy="0 0 0" xyz="-0.000200000000003065 0.0199435877845359 0.0292245259211331"/>
      <mass value="0.00853198276973456"/>
      <inertia ixx="2.89328108496468E-06" ixy="-1.57935047237397E-19" ixz="-1.93980378593255E-19" iyy="1.86719750325683E-06" iyz="-1.21858577871576E-06" izz="1.21905238907251E-06"/>
    </inertial>
    <visual>
      <origin rpy="0 0 0" xyz="0 0 0"/>
      <geometry>
        <mesh filename="/home/yanxi/curobo/src/curobo/content/assets/robot/iiwa_allegro_description/meshes/robotiq/visual/robotiq_arg2f_140_outer_knuckle.stl"/>
      </geometry>
      <material name="">
        <color rgba="0.792156862745098 0.819607843137255 0.933333333333333 1"/>
      </material>
    </visual>
    <collision>
      <origin rpy="0 0 0" xyz="0 0 0"/>
      <geometry>
        <mesh filename="/home/yanxi/curobo/src/curobo/content/assets/robot/iiwa_allegro_description/meshes/robotiq/collision/robotiq_arg2f_140_outer_knuckle.stl"/>
      </geometry>
    </collision>
  </link>
  <link name="robotiq_left_outer_finger">
    <inertial>
      <origin rpy="0 0 0" xyz="0.00030115855001899 0.0373907951953854 -0.0208027427000385"/>
      <mass value="0.022614240507152"/>
      <inertia ixx="1.52518312458174E-05" ixy="9.76583423954399E-10" ixz="-5.43838577022588E-10" iyy="6.17694243867776E-06" iyz="6.78636130740228E-06" izz="1.16494917907219E-05"/>
    </inertial>
    <visual>
      <origin rpy="0 0 0" xyz="0 0 0"/>
      <geometry>
        <mesh filename="/home/yanxi/curobo/src/curobo/content/assets/robot/iiwa_allegro_description/meshes/robotiq/visual/robotiq_arg2f_140_outer_finger.stl"/>
      </geometry>
      <material name="">
        <color rgba="0.1 0.1 0.1 1"/>
      </material>
    </visual>
    <collision>
      <origin rpy="0 0 0" xyz="0 0 0"/>
      <geometry>
        <mesh filename="/home/yanxi/curobo/src/curobo/content/assets/robot/iiwa_allegro_description/meshes/robotiq/collision/robotiq_arg2f_140_outer_finger.stl"/>
      </geometry>
    </collision>
  </link>
  <link name="robotiq_left_inner_finger">
    <inertial>
      <origin rpy="0 0 0" xyz="0.000299999999999317 0.0160078233491243 -0.0136945669206257"/>
      <mass value="0.0104003125914103"/>
      <inertia ixx="2.71909453810972E-06" ixy="1.35402465472579E-21" ixz="-7.1817349065269E-22" iyy="7.69100314106116E-07" iyz="6.74715432769696E-07" izz="2.30315190420171E-06"/>
    </inertial>
    <visual>
      <origin rpy="0 0 0" xyz="0 0 0"/>
      <geometry>
        <mesh filename="/home/yanxi/curobo/src/curobo/content/assets/robot/iiwa_allegro_description/meshes/robotiq/visual/robotiq_arg2f_140_inner_finger.stl"/>
      </geometry>
      <material name="">
        <color rgba="0.1 0.1 0.1 1"/>
      </material>
    </visual>
    <collision>
      <origin rpy="0 0 0" xyz="0 0 0"/>
      <geometry>
        <mesh filename="/home/yanxi/curobo/src/curobo/content/assets/robot/iiwa_allegro_description/meshes/robotiq/collision/robotiq_arg2f_140_inner_finger.stl"/>
      </geometry>
    </collision>
  </link>
  <link name="robotiq_left_inner_finger_pad">
    <visual>
      <origin rpy="0 0 0" xyz="0 0 0"/>
      <geometry>
        <box size="0.027 0.065 0.0075"/>
      </geometry>
      <material name="">
        <color rgba="0.9 0.9 0.9 1"/>
      </material>
    </visual>
    <collision>
      <origin rpy="0 0 0" xyz="0 0 0"/>
      <geometry>
        <box size="0.03 0.07 0.0075"/>
      </geometry>
      <material name="">
        <color rgba="0.9 0.0 0.0 1"/>
      </material>
    </collision>
  </link>
  <link name="robotiq_left_inner_knuckle">
    <inertial>
      <origin rpy="0 0 0" xyz="0.000123011831763771 0.0507850843201817 0.00103968640075166"/>
      <mass value="0.0271177346495152"/>
      <inertia ixx="2.61910379223783E-05" ixy="-2.43616858946494E-07" ixz="-6.37789906117123E-09" iyy="2.8270243746167E-06" iyz="-5.37200748039765E-07" izz="2.83695868220296E-05"/>
    </inertial>
    <visual>
      <origin rpy="0 0 0" xyz="0 0 0"/>
      <geometry>
        <mesh filename="/home/yanxi/curobo/src/curobo/content/assets/robot/iiwa_allegro_description/meshes/robotiq/visual/robotiq_arg2f_140_inner_knuckle.stl"/>
      </geometry>
      <material name="">
        <color rgba="0.1 0.1 0.1 1"/>
      </material>
    </visual>
    <collision>
      <origin rpy="0 0 0" xyz="0 0 0"/>
      <geometry>
        <mesh filename="/home/yanxi/curobo/src/curobo/content/assets/robot/iiwa_allegro_description/meshes/robotiq/collision/robotiq_arg2f_140_inner_knuckle.stl"/>
      </geometry>
    </collision>
  </link>
  <link name="robotiq_right_outer_knuckle">
    <inertial>
      <origin rpy="0 0 0" xyz="-0.000200000000003065 0.0199435877845359 0.0292245259211331"/>
      <mass value="0.00853198276973456"/>
      <inertia ixx="2.89328108496468E-06" ixy="-1.57935047237397E-19" ixz="-1.93980378593255E-19" iyy="1.86719750325683E-06" iyz="-1.21858577871576E-06" izz="1.21905238907251E-06"/>
    </inertial>
    <visual>
      <origin rpy="0 0 0" xyz="0 0 0"/>
      <geometry>
        <mesh filename="/home/yanxi/curobo/src/curobo/content/assets/robot/iiwa_allegro_description/meshes/robotiq/visual/robotiq_arg2f_140_outer_knuckle.stl"/>
      </geometry>
      <material name="">
        <color rgba="0.792156862745098 0.819607843137255 0.933333333333333 1"/>
      </material>
    </visual>
    <collision>
      <origin rpy="0 0 0" xyz="0 0 0"/>
      <geometry>
        <mesh filename="/home/yanxi/curobo/src/curobo/content/assets/robot/iiwa_allegro_description/meshes/robotiq/collision/robotiq_arg2f_140_outer_knuckle.stl"/>
      </geometry>
    </collision>
  </link>
  <link name="robotiq_right_outer_finger">
    <inertial>
      <origin rpy="0 0 0" xyz="0.00030115855001899 0.0373907951953854 -0.0208027427000385"/>
      <mass value="0.022614240507152"/>
      <inertia ixx="1.52518312458174E-05" ixy="9.76583423954399E-10" ixz="-5.43838577022588E-10" iyy="6.17694243867776E-06" iyz="6.78636130740228E-06" izz="1.16494917907219E-05"/>
    </inertial>
    <visual>
      <origin rpy="0 0 0" xyz="0 0 0"/>
      <geometry>
        <mesh filename="/home/yanxi/curobo/src/curobo/content/assets/robot/iiwa_allegro_description/meshes/robotiq/visual/robotiq_arg2f_140_outer_finger.stl"/>
      </geometry>
      <material name="">
        <color rgba="0.1 0.1 0.1 1"/>
      </material>
    </visual>
    <collision>
      <origin rpy="0 0 0" xyz="0 0 0"/>
      <geometry>
        <mesh filename="/home/yanxi/curobo/src/curobo/content/assets/robot/iiwa_allegro_description/meshes/robotiq/collision/robotiq_arg2f_140_outer_finger.stl"/>
      </geometry>
    </collision>
  </link>
  <link name="robotiq_right_inner_finger">
    <inertial>
      <origin rpy="0 0 0" xyz="0.000299999999999317 0.0160078233491243 -0.0136945669206257"/>
      <mass value="0.0104003125914103"/>
      <inertia ixx="2.71909453810972E-06" ixy="1.35402465472579E-21" ixz="-7.1817349065269E-22" iyy="7.69100314106116E-07" iyz="6.74715432769696E-07" izz="2.30315190420171E-06"/>
    </inertial>
    <visual>
      <origin rpy="0 0 0" xyz="0 0 0"/>
      <geometry>
        <mesh filename="/home/yanxi/curobo/src/curobo/content/assets/robot/iiwa_allegro_description/meshes/robotiq/visual/robotiq_arg2f_140_inner_finger.stl"/>
      </geometry>
      <material name="">
        <color rgba="0.1 0.1 0.1 1"/>
      </material>
    </visual>
    <collision>
      <origin rpy="0 0 0" xyz="0 0 0"/>
      <geometry>
        <mesh filename="/home/yanxi/curobo/src/curobo/content/assets/robot/iiwa_allegro_description/meshes/robotiq/collision/robotiq_arg2f_140_inner_finger.stl"/>
      </geometry>
    </collision>
  </link>
  <link name="robotiq_right_inner_finger_pad">
    <visual>
      <origin rpy="0 0 0" xyz="0 0 0"/>
      <geometry>
        <box size="0.027 0.065 0.0075"/>
      </geometry>
      <material name="">
        <color rgba="0.9 0.9 0.9 1"/>
      </material>
    </visual>
    <collision>
      <origin rpy="0 0 0" xyz="0 0 0"/>
      <geometry>
        <box size="0.03 0.07 0.0075"/>
      </geometry>
      <material name="">
        <color rgba="0.9 0.0 0.0 1"/>
      </material>
    </collision>
  </link>
  <link name="robotiq_right_inner_knuckle">
    <inertial>
      <origin rpy="0 0 0" xyz="0.000123011831763771 0.0507850843201817 0.00103968640075166"/>
      <mass value="0.0271177346495152"/>
      <inertia ixx="2.61910379223783E-05" ixy="-2.43616858946494E-07" ixz="-6.37789906117123E-09" iyy="2.8270243746167E-06" iyz="-5.37200748039765E-07" izz="2.83695868220296E-05"/>
    </inertial>
    <visual>
      <origin rpy="0 0 0" xyz="0 0 0"/>
      <geometry>
        <mesh filename="/home/yanxi/curobo/src/curobo/content/assets/robot/iiwa_allegro_description/meshes/robotiq/visual/robotiq_arg2f_140_inner_knuckle.stl"/>
      </geometry>
      <material name="">
        <color rgba="0.1 0.1 0.1 1"/>
      </material>
    </visual>
    <collision>
      <origin rpy="0 0 0" xyz="0 0 0"/>
      <geometry>
        <mesh filename="/home/yanxi/curobo/src/curobo/content/assets/robot/iiwa_allegro_description/meshes/robotiq/collision/robotiq_arg2f_140_inner_knuckle.stl"/>
      </geometry>
    </collision>
  </link>
  <joint name="robotiq_finger_joint" type="revolute">
    <origin rpy="2.2957963267948966 0 0" xyz="0 -0.030601 0.054905"/>
    <parent link="robotiq_base_link"/>
    <child link="robotiq_left_outer_knuckle"/>
    <axis xyz="-1 0 0"/>
    <limit effort="1000" lower="0" upper="0.7" velocity="2.0"/>
  </joint>
  <joint name="robotiq_left_outer_finger_joint" type="fixed">
    <origin rpy="0 0 0" xyz="0 0.01821998610742 0.0260018192872234"/>
    <parent link="robotiq_left_outer_knuckle"/>
    <child link="robotiq_left_outer_finger"/>
    <axis xyz="1 0 0"/>
  </joint>
  <joint name="robotiq_left_inner_knuckle_joint" type="revolute">
    <origin rpy="2.2957963267948966 0 0" xyz="0 -0.0127 0.06142"/>
    <parent link="robotiq_base_link"/>
    <child link="robotiq_left_inner_knuckle"/>
    <axis xyz="1 0 0"/>
    <limit effort="1000" lower="0" upper="0.8757" velocity="2.0"/>
    <mimic joint="robotiq_finger_joint" multiplier="-1" offset="0"/>
  </joint>
  <joint name="robotiq_left_inner_finger_joint" type="revolute">
    <origin rpy="-0.725 0 0" xyz="0 0.0817554015893473 -0.0282203446692936"/>
    <parent link="robotiq_left_outer_finger"/>
    <child link="robotiq_left_inner_finger"/>
    <axis xyz="1 0 0"/>
    <limit effort="1000" lower="0" upper="0.8757" velocity="2.0"/>
    <mimic joint="robotiq_finger_joint" multiplier="1" offset="0"/>
  </joint>
  <joint name="robotiq_left_inner_finger_pad_joint" type="fixed">
    <origin rpy="0 0 0" xyz="0 0.0457554015893473 -0.0272203446692936"/>
    <parent link="robotiq_left_inner_finger"/>
    <child link="robotiq_left_inner_finger_pad"/>
    <axis xyz="0 0 1"/>
  </joint>
  <joint name="robotiq_right_outer_knuckle_joint" type="revolute">
    <origin rpy="2.2957963267948966 0 3.141592653589793" xyz="0 0.030601 0.054905"/>
    <parent link="robotiq_base_link"/>
    <child link="robotiq_right_outer_knuckle"/>
    <axis xyz="1 0 0"/>
    <limit effort="1000" lower="0" upper="0.725" velocity="2.0"/>
    <mimic joint="robotiq_finger_joint" multiplier="-1" offset="0"/>
  </joint>
  <joint name="robotiq_right_outer_finger_joint" type="fixed">
    <origin rpy="0 0 0" xyz="0 0.01821998610742 0.0260018192872234"/>
    <parent link="robotiq_right_outer_knuckle"/>
    <child link="robotiq_right_outer_finger"/>
    <axis xyz="1 0 0"/>
  </joint>
  <joint name="robotiq_right_inner_knuckle_joint" type="revolute">
    <origin rpy="2.2957963267948966 0 -3.141592653589793" xyz="0 0.0127 0.06142"/>
    <parent link="robotiq_base_link"/>
    <child link="robotiq_right_inner_knuckle"/>
    <axis xyz="1 0 0"/>
    <limit effort="1000" lower="0" upper="0.8757" velocity="2.0"/>
    <mimic joint="robotiq_finger_joint" multiplier="-1" offset="0"/>
  </joint>
  <joint name="robotiq_right_inner_finger_joint" type="revolute">
    <origin rpy="-0.725 0 0" xyz="0 0.0817554015893473 -0.0282203446692936"/>
    <parent link="robotiq_right_outer_finger"/>
    <child link="robotiq_right_inner_finger"/>
    <axis xyz="1 0 0"/>
    <limit effort="1000" lower="0" upper="0.8757" velocity="2.0"/>
    <mimic joint="robotiq_finger_joint" multiplier="1" offset="0"/>
  </joint>
  <joint name="robotiq_right_inner_finger_pad_joint" type="fixed">
    <origin rpy="0 0 0" xyz="0 0.0457554015893473 -0.0272203446692936"/>
    <parent link="robotiq_right_inner_finger"/>
    <child link="robotiq_right_inner_finger_pad"/>
    <axis xyz="0 0 1"/>
  </joint>
  <transmission name="robotiq_finger_joint_trans">
    <type>transmission_interface/SimpleTransmission</type>
    <joint name="robotiq_finger_joint">
      <hardwareInterface>PositionJointInterface</hardwareInterface>
    </joint>
    <actuator name="robotiq_finger_joint_motor">
      <mechanicalReduction>1</mechanicalReduction>
    </actuator>
  </transmission>
  <!-- Mount + screws -->
  <link name="robotiq_to_iiwa_mount">
    <inertial>
      <origin rpy="0 0 0" xyz="0 0 0"/>
      <mass value="0.064"/>
      <inertia ixx="2.0368000000000002e-05" ixy="0.0" ixz="0.0" iyy="2.0368000000000002e-05" iyz="0.0" izz="3.9200000000000004e-05"/>
    </inertial>
    <visual>
      <origin rpy="0 0 0" xyz="0 0 0"/>
      <geometry>
        <cylinder length="0.012" radius="0.035"/>
      </geometry>
      <material name="black"/>
    </visual>
    <collision>
      <origin rpy="0 0 0" xyz="0 0 0"/>
      <geometry>
        <cylinder length="0.012" radius="0.035"/>
      </geometry>
    </collision>
  </link>
  <joint name="iiwa_to_mount" type="fixed">
    <parent link="iiwa_link_7"/>
    <child link="robotiq_to_iiwa_mount"/>
    <origin rpy="0 0 3.141592653589793" xyz="0 0 0.051"/>
  </joint>
  <joint name="robotiq_mount_to_base_link" type="fixed">
    <parent link="robotiq_to_iiwa_mount"/>
    <child link="robotiq_base_link"/>
    <origin rpy="0 0 1.5708" xyz="0 0 0.006"/>
  </joint>
  <!-- ROS Control -->
  <gazebo>
    <plugin filename="libgazebo_ros_control.so" name="gazebo_ros_control">
      <!-- This tag gets rid of an error that popped up in version 8.6 -->
      <legacyModeNS>true</legacyModeNS>
    </plugin>
  </gazebo>
  <link name="grasp_frame">
    <inertial>
      <!-- Dummy inertial parameters to avoid link lumping-->
      <mass value="0.01"/>
      <inertia ixx="0.0001" ixy="0.0" ixz="0.0" iyy="0.0001" iyz="0.0" izz="0.0001"/>
      <origin rpy="0 0 0" xyz="0 0 0"/>
    </inertial>
  </link>
  <joint name="grasp_joint" type="fixed">
    <origin rpy="0 0 0.0" xyz="0 0 0.2"/>
    <axis xyz="0 0 1"/>
    <parent link="robotiq_to_iiwa_mount"/>
    <child link="grasp_frame"/>
  </joint>
</robot>

